Workbook
Name BridgeCodes: #REF!
Name JunctionCode: #REF!
Name JunctionXML: #REF!
Name Scheme: #REF!
Name SchemeXML: #REF!

Sheet Areas
B2: AREA INPUTS
B4: DETAILS & PROP TYPE | I4: MEASUREMENTS | M4: WALLS | V4: ROOFS | AC4: FLOORS | AH4: OPENINGS | AX4: VENT & DHW | BH4: RENEWABLES | BS4: CHECKS
AH6: Front Door | AM6: Windows
B7: Dwelling | C7: Level | D7: Front Door Orientation | E7: Terrace Type | F7: Position | G7: Sheltered Sides | I7: Floor Area | J7: Storey Height | K7: Living Room Area | M7: External Walls 1 (Cavity) (ex Windows) | N7: External Walls 2 (Dormer) (ex Windows) | O7: External Walls 3 (Dwarf Walls) | P7: External Walls 4 (Semi Exposed) | Q7: Party Walls to Circulation | R7: Party Walls to Flats | S7: Internal Paritions | T7: Internal Partitions Doubled | V7: Roof Type 1 (Pitched) | W7: Roof Type 2 (Timber Flat) | X7: Roof Type 3 (Semi Exposed) | Y7: Roof Type 4 (Cold Roof) | Z7: Roof Type 5 (Concrete Flat) | AA7: Party Ceiling | AC7: Ground Floor | AD7: Exposed Floor | AE7: Semi Exposed Floor | AF7: Party Floor | AH7: North East | AI7: South East | AJ7: South West | AK7: North West | AM7: North | AN7: North East | AO7: East | AP7: South East | AQ7: South | AR7: South West | AS7: West | AT7: North West | AV7: Roof Light | AX7: Bathrooms / Shower Rooms | AY7: WC / Utility | AZ7: Shower Bath | BA7: Standard Bath | BB7: Separate Shower | BC7: Wet Rooms Ex Kitchen | BD7: Bath Count | BE7: Showers | BF7: Cooled Area | BH7: Total Floor Area | BI7: Fraction of Floor Area | BK7: PV Capacity (kW) | BM7: Number of Panels | BN7: Panel Capacity (kW) | BO7: Peak Capacity (kW) | BP7: Orientation | BQ7: Pitch (°) | BS7: Glazing Area (27) | BT7: Door Area (26) | BU7: Net Area of External Elements (31) | BV7: Volume | BX7: Total Area in Sheet (m2) | BY7: Total in Export (m2)
B8: {=_xlfn._xlws.SORT(_xlfn.UNIQUE(_xlfn._xlws.FILTER('Pasted Areas'!$K$6:$K$1000,('Pasted Areas'!$K$6:$K$1000<>"")*('Pasted Areas'!$K$6:$K$1000<>0))))} -> Flat 01 | C8: 0 | D8: NW | E8: End | F8: GF | G8: 2 | I8: =SUM(AC8:AF8) -> 53.96 | J8: 2.5 | K8: =SUMIFS('Pasted Areas'!$E:$E,'Pasted Areas'!$K:$K,B8,'Pasted Areas'!$C:$C,"*Living*") -> 24.62 | M8: =SUMIFS('Pasted Areas'!$E:$E,'Pasted Areas'!$K:$K,$B8,'Pasted Areas'!$C:$C,"*External Wall Area 1*") -> 31.02 | N8: =SUMIFS('Pasted Areas'!$E:$E,'Pasted Areas'!$K:$K,$B8,'Pasted Areas'!$C:$C,"*External Wall Area 2*") -> 0 | O8: =SUMIFS('Pasted Areas'!$E:$E,'Pasted Areas'!$K:$K,$B8,'Pasted Areas'!$C:$C,"*External Wall Area 3*") -> 0 | P8: =SUMIFS('Pasted Areas'!$E:$E,'Pasted Areas'!$K:$K,$B8,'Pasted Areas'!$C:$C,"*External Wall Area 4*") -> 12.95 | Q8: =SUMIFS('Pasted Areas'!$E:$E,'Pasted Areas'!$K:$K,$B8,'Pasted Areas'!$C:$C,"*Party Walls to Corridors*") -> 24.68 | R8: =SUMIFS('Pasted Areas'!$E:$E,'Pasted Areas'!$K:$K,$B8,'Pasted Areas'!$C:$C,"*Party Walls to Dwelling*") -> 6.71 | S8: =SUMIFS('Pasted Areas'!$E:$E,'Pasted Areas'!$K:$K,$B8,'Pasted Areas'!$C:$C,"*Internal Partitions*") -> 44.46 | T8: =S8*2 -> 88.92 | V8: =SUMIFS('Pasted Areas'!$E:$E,'Pasted Areas'!$K:$K,$B8,'Pasted Areas'!$C:$C,"*SAP Roof 1*") -> 0 | W8: =SUMIFS('Pasted Areas'!$E:$E,'Pasted Areas'!$K:$K,$B8,'Pasted Areas'!$C:$C,"*SAP Roof 2*") -> 0 | X8: =SUMIFS('Pasted Areas'!$E:$E,'Pasted Areas'!$K:$K,$B8,'Pasted Areas'!$C:$C,"*SAP Roof 3*") -> 0 | Y8: =SUMIFS('Pasted Areas'!$E:$E,'Pasted Areas'!$K:$K,$B8,'Pasted Areas'!$C:$C,"*SAP Roof 4*") -> 0 | Z8: =SUMIFS('Pasted Areas'!$E:$E,'Pasted Areas'!$K:$K,$B8,'Pasted Areas'!$C:$C,"*SAP Roof 5*") -> 5.88 | AA8: =SUMIFS('Pasted Areas'!$E:$E,'Pasted Areas'!$K:$K,$B8,'Pasted Areas'!$C:$C,"*Party Ceiling*") -> 48.08 | AC8: =SUMIFS('Pasted Areas'!$E:$E,'Pasted Areas'!$K:$K,$B8,'Pasted Areas'!$C:$C,"*Ground Floor*") -> 53.96 | AD8: =SUMIFS('Pasted Areas'!$E:$E,'Pasted Areas'!$K:$K,$B8,'Pasted Areas'!$C:$C,"* Exposed Floor*") -> 0 | AE8: =SUMIFS('Pasted Areas'!$E:$E,'Pasted Areas'!$K:$K,$B8,'Pasted Areas'!$C:$C,"*Semi-Exposed Floor*") -> 0 | AF8: =SUMIFS('Pasted Areas'!$E:$E,'Pasted Areas'!$K:$K,$B8,'Pasted Areas'!$C:$C,"*Party Floor*") -> 0 | AH8: =SUMIFS('Pasted Areas'!$E:$E,'Pasted Areas'!$K:$K,$B8,'Pasted Areas'!$C:$C,"*Front Door*",'Pasted Areas'!$H:$H,AH$7) -> 0 | AI8: =SUMIFS('Pasted Areas'!$E:$E,'Pasted Areas'!$K:$K,$B8,'Pasted Areas'!$C:$C,"*Front Door*",'Pasted Areas'!$H:$H,AI$7) -> 0 | AJ8: =SUMIFS('Pasted Areas'!$E:$E,'Pasted Areas'!$K:$K,$B8,'Pasted Areas'!$C:$C,"*Front Door*",'Pasted Areas'!$H:$H,AJ$7) -> 0 | AK8: =SUMIFS('Pasted Areas'!$E:$E,'Pasted Areas'!$K:$K,$B8,'Pasted Areas'!$C:$C,"*Front Door*",'Pasted Areas'!$H:$H,AK$7) -> 2.12 | AM8: =SUMIFS('Pasted Areas'!$E:$E,'Pasted Areas'!$K:$K,$B8,'Pasted Areas'!$C:$C,"*Glazing*",'Pasted Areas'!$H:$H,AM$7) -> 0 | AN8: =SUMIFS('Pasted Areas'!$E:$E,'Pasted Areas'!$K:$K,$B8,'Pasted Areas'!$C:$C,"*Glazing*",'Pasted Areas'!$H:$H,AN$7) -> 0 | AO8: =SUMIFS('Pasted Areas'!$E:$E,'Pasted Areas'!$K:$K,$B8,'Pasted Areas'!$C:$C,"*Glazing*",'Pasted Areas'!$H:$H,AO$7) -> 0 | AP8: =SUMIFS('Pasted Areas'!$E:$E,'Pasted Areas'!$K:$K,$B8,'Pasted Areas'!$C:$C,"*Glazing*",'Pasted Areas'!$H:$H,AP$7) -> 0 | AQ8: =SUMIFS('Pasted Areas'!$E:$E,'Pasted Areas'!$K:$K,$B8,'Pasted Areas'!$C:$C,"*Glazing*",'Pasted Areas'!$H:$H,AQ$7) -> 0 | AR8: =SUMIFS('Pasted Areas'!$E:$E,'Pasted Areas'!$K:$K,$B8,'Pasted Areas'!$C:$C,"*Glazing*",'Pasted Areas'!$H:$H,AR$7) -> 7.97 | AS8: =SUMIFS('Pasted Areas'!$E:$E,'Pasted Areas'!$K:$K,$B8,'Pasted Areas'!$C:$C,"*Glazing*",'Pasted Areas'!$H:$H,AS$7) -> 0 | AT8: =SUMIFS('Pasted Areas'!$E:$E,'Pasted Areas'!$K:$K,$B8,'Pasted Areas'!$C:$C,"*Glazing*",'Pasted Areas'!$H:$H,AT$7) -> 1.8 | AV8: =SUMIFS('Pasted Areas'!$E:$E,'Pasted Areas'!$K:$K,$B8,'Pasted Areas'!$C:$C,"*Roof Light*") -> 0 | AX8: 1 | AY8: 0 | AZ8: 0 | BA8: 0 | BB8: 1 | BC8: =AX8+AY8 -> 1 | BD8: =AZ8+BA8 -> 0 | BE8: =AZ8+BB8 -> 1 | BF8: =SUMIFS('Pasted Areas'!$E:$E,'Pasted Areas'!$K:$K,$B8,'Pasted Areas'!$C:$C,"*Cooling Area*") -> 0 | BS8: =SUM(AM8:AT8) -> 9.77 | BT8: =SUM(AH8:AK8) -> 2.12 | BU8: =SUM(M8:P8,V8:Z8,AC8:AE8,AH8:AV8) -> 115.7 | BV8: =I8*J8 -> 134.9 | BX8: =SUM(M8:S8,V8:AV8,BF8:BF8) -> 239.63 | BY8: ='Pasted Areas'!L3 -> 5622.67
B9: Flat 02 | C9: 0 | D9: SW | E9: End | F9: GF | G9: 2 | I9: =SUM(AC9:AF9) -> 72.97 | J9: 2.5 | K9: =SUMIFS('Pasted Areas'!$E:$E,'Pasted Areas'!$K:$K,B9,'Pasted Areas'!$C:$C,"*Living*") -> 25.67 | M9: =SUMIFS('Pasted Areas'!$E:$E,'Pasted Areas'!$K:$K,$B9,'Pasted Areas'!$C:$C,"*External Wall Area 1*") -> 40.36 | N9: =SUMIFS('Pasted Areas'!$E:$E,'Pasted Areas'!$K:$K,$B9,'Pasted Areas'!$C:$C,"*External Wall Area 2*") -> 0 | O9: =SUMIFS('Pasted Areas'!$E:$E,'Pasted Areas'!$K:$K,$B9,'Pasted Areas'!$C:$C,"*External Wall Area 3*") -> 0 | P9: =SUMIFS('Pasted Areas'!$E:$E,'Pasted Areas'!$K:$K,$B9,'Pasted Areas'!$C:$C,"*External Wall Area 4*") -> 0 | Q9: =SUMIFS('Pasted Areas'!$E:$E,'Pasted Areas'!$K:$K,$B9,'Pasted Areas'!$C:$C,"*Party Walls to Corridors*") -> 24.03 | R9: =SUMIFS('Pasted Areas'!$E:$E,'Pasted Areas'!$K:$K,$B9,'Pasted Areas'!$C:$C,"*Party Walls to Dwelling*") -> 21.2 | S9: =SUMIFS('Pasted Areas'!$E:$E,'Pasted Areas'!$K:$K,$B9,'Pasted Areas'!$C:$C,"*Internal Partitions*") -> 82.97 | T9: =S9*2 -> 165.94 | V9: =SUMIFS('Pasted Areas'!$E:$E,'Pasted Areas'!$K:$K,$B9,'Pasted Areas'!$C:$C,"*SAP Roof 1*") -> 0 | W9: =SUMIFS('Pasted Areas'!$E:$E,'Pasted Areas'!$K:$K,$B9,'Pasted Areas'!$C:$C,"*SAP Roof 2*") -> 0 | X9: =SUMIFS('Pasted Areas'!$E:$E,'Pasted Areas'!$K:$K,$B9,'Pasted Areas'!$C:$C,"*SAP Roof 3*") -> 0 | Y9: =SUMIFS('Pasted Areas'!$E:$E,'Pasted Areas'!$K:$K,$B9,'Pasted Areas'!$C:$C,"*SAP Roof 4*") -> 0 | Z9: =SUMIFS('Pasted Areas'!$E:$E,'Pasted Areas'!$K:$K,$B9,'Pasted Areas'!$C:$C,"*SAP Roof 5*") -> 0 | AA9: =SUMIFS('Pasted Areas'!$E:$E,'Pasted Areas'!$K:$K,$B9,'Pasted Areas'!$C:$C,"*Party Ceiling*") -> 72.97 | AC9: =SUMIFS('Pasted Areas'!$E:$E,'Pasted Areas'!$K:$K,$B9,'Pasted Areas'!$C:$C,"*Ground Floor*") -> 72.97 | AD9: =SUMIFS('Pasted Areas'!$E:$E,'Pasted Areas'!$K:$K,$B9,'Pasted Areas'!$C:$C,"* Exposed Floor*") -> 0 | AE9: =SUMIFS('Pasted Areas'!$E:$E,'Pasted Areas'!$K:$K,$B9,'Pasted Areas'!$C:$C,"*Semi-Exposed Floor*") -> 0 | AF9: =SUMIFS('Pasted Areas'!$E:$E,'Pasted Areas'!$K:$K,$B9,'Pasted Areas'!$C:$C,"*Party Floor*") -> 0 | AH9: =SUMIFS('Pasted Areas'!$E:$E,'Pasted Areas'!$K:$K,$B9,'Pasted Areas'!$C:$C,"*Front Door*",'Pasted Areas'!$H:$H,AH$7) -> 0 | AI9: =SUMIFS('Pasted Areas'!$E:$E,'Pasted Areas'!$K:$K,$B9,'Pasted Areas'!$C:$C,"*Front Door*",'Pasted Areas'!$H:$H,AI$7) -> 0 | AJ9: =SUMIFS('Pasted Areas'!$E:$E,'Pasted Areas'!$K:$K,$B9,'Pasted Areas'!$C:$C,"*Front Door*",'Pasted Areas'!$H:$H,AJ$7) -> 0 | AK9: =SUMIFS('Pasted Areas'!$E:$E,'Pasted Areas'!$K:$K,$B9,'Pasted Areas'!$C:$C,"*Front Door*",'Pasted Areas'!$H:$H,AK$7) -> 0 | AM9: =SUMIFS('Pasted Areas'!$E:$E,'Pasted Areas'!$K:$K,$B9,'Pasted Areas'!$C:$C,"*Glazing*",'Pasted Areas'!$H:$H,AM$7) -> 0 | AN9: =SUMIFS('Pasted Areas'!$E:$E,'Pasted Areas'!$K:$K,$B9,'Pasted Areas'!$C:$C,"*Glazing*",'Pasted Areas'!$H:$H,AN$7) -> 2.88 | AO9: =SUMIFS('Pasted Areas'!$E:$E,'Pasted Areas'!$K:$K,$B9,'Pasted Areas'!$C:$C,"*Glazing*",'Pasted Areas'!$H:$H,AO$7) -> 0 | AP9: =SUMIFS('Pasted Areas'!$E:$E,'Pasted Areas'!$K:$K,$B9,'Pasted Areas'!$C:$C,"*Glazing*",'Pasted Areas'!$H:$H,AP$7) -> 0 | AQ9: =SUMIFS('Pasted Areas'!$E:$E,'Pasted Areas'!$K:$K,$B9,'Pasted Areas'!$C:$C,"*Glazing*",'Pasted Areas'!$H:$H,AQ$7) -> 0 | AR9: =SUMIFS('Pasted Areas'!$E:$E,'Pasted Areas'!$K:$K,$B9,'Pasted Areas'!$C:$C,"*Glazing*",'Pasted Areas'!$H:$H,AR$7) -> 0 | AS9: =SUMIFS('Pasted Areas'!$E:$E,'Pasted Areas'!$K:$K,$B9,'Pasted Areas'!$C:$C,"*Glazing*",'Pasted Areas'!$H:$H,AS$7) -> 0 | AT9: =SUMIFS('Pasted Areas'!$E:$E,'Pasted Areas'!$K:$K,$B9,'Pasted Areas'!$C:$C,"*Glazing*",'Pasted Areas'!$H:$H,AT$7) -> 8.84 | AV9: =SUMIFS('Pasted Areas'!$E:$E,'Pasted Areas'!$K:$K,$B9,'Pasted Areas'!$C:$C,"*Roof Light*") -> 0 | AX9: 2 | AY9: 0 | AZ9: 1 | BA9: 0 | BB9: 1 | BC9: =AX9+AY9 -> 2 | BD9: =AZ9+BA9 -> 1 | BE9: =AZ9+BB9 -> 2 | BF9: =SUMIFS('Pasted Areas'!$E:$E,'Pasted Areas'!$K:$K,$B9,'Pasted Areas'!$C:$C,"*Cooling Area*") -> 0 | BS9: =SUM(AM9:AT9) -> 11.72 | BT9: =SUM(AH9:AK9) -> 0 | BU9: =SUM(M9:P9,V9:Z9,AC9:AE9,AH9:AV9) -> 125.05 | BV9: =I9*J9 -> 182.425 | BX9: =SUM(M9:S9,V9:AV9,BF9:BF9) -> 326.22
B10: Flat 03 | C10: 0 | D10: W | E10: Mid | F10: GF | G10: 3 | I10: =SUM(AC10:AF10) -> 65.53 | J10: 2.5 | K10: =SUMIFS('Pasted Areas'!$E:$E,'Pasted Areas'!$K:$K,B10,'Pasted Areas'!$C:$C,"*Living*") -> 25.73 | M10: =SUMIFS('Pasted Areas'!$E:$E,'Pasted Areas'!$K:$K,$B10,'Pasted Areas'!$C:$C,"*External Wall Area 1*") -> 26.04 | N10: =SUMIFS('Pasted Areas'!$E:$E,'Pasted Areas'!$K:$K,$B10,'Pasted Areas'!$C:$C,"*External Wall Area 2*") -> 0 | O10: =SUMIFS('Pasted Areas'!$E:$E,'Pasted Areas'!$K:$K,$B10,'Pasted Areas'!$C:$C,"*External Wall Area 3*") -> 0 | P10: =SUMIFS('Pasted Areas'!$E:$E,'Pasted Areas'!$K:$K,$B10,'Pasted Areas'!$C:$C,"*External Wall Area 4*") -> 0 | Q10: =SUMIFS('Pasted Areas'!$E:$E,'Pasted Areas'!$K:$K,$B10,'Pasted Areas'!$C:$C,"*Party Walls to Corridors*") -> 21.18 | R10: =SUMIFS('Pasted Areas'!$E:$E,'Pasted Areas'!$K:$K,$B10,'Pasted Areas'!$C:$C,"*Party Walls to Dwelling*") -> 42.99 | S10: =SUMIFS('Pasted Areas'!$E:$E,'Pasted Areas'!$K:$K,$B10,'Pasted Areas'!$C:$C,"*Internal Partitions*") -> 59.6 | T10: =S10*2 -> 119.2 | V10: =SUMIFS('Pasted Areas'!$E:$E,'Pasted Areas'!$K:$K,$B10,'Pasted Areas'!$C:$C,"*SAP Roof 1*") -> 0 | W10: =SUMIFS('Pasted Areas'!$E:$E,'Pasted Areas'!$K:$K,$B10,'Pasted Areas'!$C:$C,"*SAP Roof 2*") -> 0 | X10: =SUMIFS('Pasted Areas'!$E:$E,'Pasted Areas'!$K:$K,$B10,'Pasted Areas'!$C:$C,"*SAP Roof 3*") -> 0 | Y10: =SUMIFS('Pasted Areas'!$E:$E,'Pasted Areas'!$K:$K,$B10,'Pasted Areas'!$C:$C,"*SAP Roof 4*") -> 0 | Z10: =SUMIFS('Pasted Areas'!$E:$E,'Pasted Areas'!$K:$K,$B10,'Pasted Areas'!$C:$C,"*SAP Roof 5*") -> 0 | AA10: =SUMIFS('Pasted Areas'!$E:$E,'Pasted Areas'!$K:$K,$B10,'Pasted Areas'!$C:$C,"*Party Ceiling*") -> 65.53 | AC10: =SUMIFS('Pasted Areas'!$E:$E,'Pasted Areas'!$K:$K,$B10,'Pasted Areas'!$C:$C,"*Ground Floor*") -> 65.53 | AD10: =SUMIFS('Pasted Areas'!$E:$E,'Pasted Areas'!$K:$K,$B10,'Pasted Areas'!$C:$C,"* Exposed Floor*") -> 0 | AE10: =SUMIFS('Pasted Areas'!$E:$E,'Pasted Areas'!$K:$K,$B10,'Pasted Areas'!$C:$C,"*Semi-Exposed Floor*") -> 0 | AF10: =SUMIFS('Pasted Areas'!$E:$E,'Pasted Areas'!$K:$K,$B10,'Pasted Areas'!$C:$C,"*Party Floor*") -> 0 | AH10: =SUMIFS('Pasted Areas'!$E:$E,'Pasted Areas'!$K:$K,$B10,'Pasted Areas'!$C:$C,"*Front Door*",'Pasted Areas'!$H:$H,AH$7) -> 0 | AI10: =SUMIFS('Pasted Areas'!$E:$E,'Pasted Areas'!$K:$K,$B10,'Pasted Areas'!$C:$C,"*Front Door*",'Pasted Areas'!$H:$H,AI$7) -> 0 | AJ10: =SUMIFS('Pasted Areas'!$E:$E,'Pasted Areas'!$K:$K,$B10,'Pasted Areas'!$C:$C,"*Front Door*",'Pasted Areas'!$H:$H,AJ$7) -> 0 | AK10: =SUMIFS('Pasted Areas'!$E:$E,'Pasted Areas'!$K:$K,$B10,'Pasted Areas'!$C:$C,"*Front Door*",'Pasted Areas'!$H:$H,AK$7) -> 0 | AM10: =SUMIFS('Pasted Areas'!$E:$E,'Pasted Areas'!$K:$K,$B10,'Pasted Areas'!$C:$C,"*Glazing*",'Pasted Areas'!$H:$H,AM$7) -> 0 | AN10: =SUMIFS('Pasted Areas'!$E:$E,'Pasted Areas'!$K:$K,$B10,'Pasted Areas'!$C:$C,"*Glazing*",'Pasted Areas'!$H:$H,AN$7) -> 1.8 | AO10: =SUMIFS('Pasted Areas'!$E:$E,'Pasted Areas'!$K:$K,$B10,'Pasted Areas'!$C:$C,"*Glazing*",'Pasted Areas'!$H:$H,AO$7) -> 4.68 | AP10: =SUMIFS('Pasted Areas'!$E:$E,'Pasted Areas'!$K:$K,$B10,'Pasted Areas'!$C:$C,"*Glazing*",'Pasted Areas'!$H:$H,AP$7) -> 1.89 | AQ10: =SUMIFS('Pasted Areas'!$E:$E,'Pasted Areas'!$K:$K,$B10,'Pasted Areas'!$C:$C,"*Glazing*",'Pasted Areas'!$H:$H,AQ$7) -> 0 | AR10: =SUMIFS('Pasted Areas'!$E:$E,'Pasted Areas'!$K:$K,$B10,'Pasted Areas'!$C:$C,"*Glazing*",'Pasted Areas'!$H:$H,AR$7) -> 0 | AS10: =SUMIFS('Pasted Areas'!$E:$E,'Pasted Areas'!$K:$K,$B10,'Pasted Areas'!$C:$C,"*Glazing*",'Pasted Areas'!$H:$H,AS$7) -> 0 | AT10: =SUMIFS('Pasted Areas'!$E:$E,'Pasted Areas'!$K:$K,$B10,'Pasted Areas'!$C:$C,"*Glazing*",'Pasted Areas'!$H:$H,AT$7) -> 0 | AV10: =SUMIFS('Pasted Areas'!$E:$E,'Pasted Areas'!$K:$K,$B10,'Pasted Areas'!$C:$C,"*Roof Light*") -> 0 | AX10: 1 | AY10: 0 | AZ10: 1 | BA10: 0 | BB10: 0 | BC10: =AX10+AY10 -> 1 | BD10: =AZ10+BA10 -> 1 | BE10: =AZ10+BB10 -> 1 | BF10: =SUMIFS('Pasted Areas'!$E:$E,'Pasted Areas'!$K:$K,$B10,'Pasted Areas'!$C:$C,"*Cooling Area*") -> 0 | BS10: =SUM(AM10:AT10) -> 8.37 | BT10: =SUM(AH10:AK10) -> 0 | BU10: =SUM(M10:P10,V10:Z10,AC10:AE10,AH10:AV10) -> 99.94 | BV10: =I10*J10 -> 163.825 | BX10: =SUM(M10:S10,V10:AV10,BF10:BF10) -> 289.24
B11: Flat 04 | C11: 0 | D11: W | E11: Mid | F11: GF | G11: 3 | I11: =SUM(AC11:AF11) -> 51.69 | J11: 2.5 | K11: =SUMIFS('Pasted Areas'!$E:$E,'Pasted Areas'!$K:$K,B11,'Pasted Areas'!$C:$C,"*Living*") -> 23.6 | M11: =SUMIFS('Pasted Areas'!$E:$E,'Pasted Areas'!$K:$K,$B11,'Pasted Areas'!$C:$C,"*External Wall Area 1*") -> 13.18 | N11: =SUMIFS('Pasted Areas'!$E:$E,'Pasted Areas'!$K:$K,$B11,'Pasted Areas'!$C:$C,"*External Wall Area 2*") -> 0 | O11: =SUMIFS('Pasted Areas'!$E:$E,'Pasted Areas'!$K:$K,$B11,'Pasted Areas'!$C:$C,"*External Wall Area 3*") -> 0 | P11: =SUMIFS('Pasted Areas'!$E:$E,'Pasted Areas'!$K:$K,$B11,'Pasted Areas'!$C:$C,"*External Wall Area 4*") -> 0 | Q11: =SUMIFS('Pasted Areas'!$E:$E,'Pasted Areas'!$K:$K,$B11,'Pasted Areas'!$C:$C,"*Party Walls to Corridors*") -> 16.76 | R11: =SUMIFS('Pasted Areas'!$E:$E,'Pasted Areas'!$K:$K,$B11,'Pasted Areas'!$C:$C,"*Party Walls to Dwelling*") -> 50.22 | S11: =SUMIFS('Pasted Areas'!$E:$E,'Pasted Areas'!$K:$K,$B11,'Pasted Areas'!$C:$C,"*Internal Partitions*") -> 44.84 | T11: =S11*2 -> 89.68 | V11: =SUMIFS('Pasted Areas'!$E:$E,'Pasted Areas'!$K:$K,$B11,'Pasted Areas'!$C:$C,"*SAP Roof 1*") -> 0 | W11: =SUMIFS('Pasted Areas'!$E:$E,'Pasted Areas'!$K:$K,$B11,'Pasted Areas'!$C:$C,"*SAP Roof 2*") -> 0 | X11: =SUMIFS('Pasted Areas'!$E:$E,'Pasted Areas'!$K:$K,$B11,'Pasted Areas'!$C:$C,"*SAP Roof 3*") -> 0 | Y11: =SUMIFS('Pasted Areas'!$E:$E,'Pasted Areas'!$K:$K,$B11,'Pasted Areas'!$C:$C,"*SAP Roof 4*") -> 0 | Z11: =SUMIFS('Pasted Areas'!$E:$E,'Pasted Areas'!$K:$K,$B11,'Pasted Areas'!$C:$C,"*SAP Roof 5*") -> 0 | AA11: =SUMIFS('Pasted Areas'!$E:$E,'Pasted Areas'!$K:$K,$B11,'Pasted Areas'!$C:$C,"*Party Ceiling*") -> 51.69 | AC11: =SUMIFS('Pasted Areas'!$E:$E,'Pasted Areas'!$K:$K,$B11,'Pasted Areas'!$C:$C,"*Ground Floor*") -> 51.69 | AD11: =SUMIFS('Pasted Areas'!$E:$E,'Pasted Areas'!$K:$K,$B11,'Pasted Areas'!$C:$C,"* Exposed Floor*") -> 0 | AE11: =SUMIFS('Pasted Areas'!$E:$E,'Pasted Areas'!$K:$K,$B11,'Pasted Areas'!$C:$C,"*Semi-Exposed Floor*") -> 0 | AF11: =SUMIFS('Pasted Areas'!$E:$E,'Pasted Areas'!$K:$K,$B11,'Pasted Areas'!$C:$C,"*Party Floor*") -> 0 | AH11: =SUMIFS('Pasted Areas'!$E:$E,'Pasted Areas'!$K:$K,$B11,'Pasted Areas'!$C:$C,"*Front Door*",'Pasted Areas'!$H:$H,AH$7) -> 0 | AI11: =SUMIFS('Pasted Areas'!$E:$E,'Pasted Areas'!$K:$K,$B11,'Pasted Areas'!$C:$C,"*Front Door*",'Pasted Areas'!$H:$H,AI$7) -> 0 | AJ11: =SUMIFS('Pasted Areas'!$E:$E,'Pasted Areas'!$K:$K,$B11,'Pasted Areas'!$C:$C,"*Front Door*",'Pasted Areas'!$H:$H,AJ$7) -> 0 | AK11: =SUMIFS('Pasted Areas'!$E:$E,'Pasted Areas'!$K:$K,$B11,'Pasted Areas'!$C:$C,"*Front Door*",'Pasted Areas'!$H:$H,AK$7) -> 0 | AM11: =SUMIFS('Pasted Areas'!$E:$E,'Pasted Areas'!$K:$K,$B11,'Pasted Areas'!$C:$C,"*Glazing*",'Pasted Areas'!$H:$H,AM$7) -> 0 | AN11: =SUMIFS('Pasted Areas'!$E:$E,'Pasted Areas'!$K:$K,$B11,'Pasted Areas'!$C:$C,"*Glazing*",'Pasted Areas'!$H:$H,AN$7) -> 0 | AO11: =SUMIFS('Pasted Areas'!$E:$E,'Pasted Areas'!$K:$K,$B11,'Pasted Areas'!$C:$C,"*Glazing*",'Pasted Areas'!$H:$H,AO$7) -> 7.04 | AP11: =SUMIFS('Pasted Areas'!$E:$E,'Pasted Areas'!$K:$K,$B11,'Pasted Areas'!$C:$C,"*Glazing*",'Pasted Areas'!$H:$H,AP$7) -> 0 | AQ11: =SUMIFS('Pasted Areas'!$E:$E,'Pasted Areas'!$K:$K,$B11,'Pasted Areas'!$C:$C,"*Glazing*",'Pasted Areas'!$H:$H,AQ$7) -> 0 | AR11: =SUMIFS('Pasted Areas'!$E:$E,'Pasted Areas'!$K:$K,$B11,'Pasted Areas'!$C:$C,"*Glazing*",'Pasted Areas'!$H:$H,AR$7) -> 0 | AS11: =SUMIFS('Pasted Areas'!$E:$E,'Pasted Areas'!$K:$K,$B11,'Pasted Areas'!$C:$C,"*Glazing*",'Pasted Areas'!$H:$H,AS$7) -> 0 | AT11: =SUMIFS('Pasted Areas'!$E:$E,'Pasted Areas'!$K:$K,$B11,'Pasted Areas'!$C:$C,"*Glazing*",'Pasted Areas'!$H:$H,AT$7) -> 0 | AV11: =SUMIFS('Pasted Areas'!$E:$E,'Pasted Areas'!$K:$K,$B11,'Pasted Areas'!$C:$C,"*Roof Light*") -> 0 | AX11: 1 | AY11: 0 | AZ11: 1 | BA11: 0 | BB11: 0 | BC11: =AX11+AY11 -> 1 | BD11: =AZ11+BA11 -> 1 | BE11: =AZ11+BB11 -> 1 | BF11: =SUMIFS('Pasted Areas'!$E:$E,'Pasted Areas'!$K:$K,$B11,'Pasted Areas'!$C:$C,"*Cooling Area*") -> 0 | BS11: =SUM(AM11:AT11) -> 7.04 | BT11: =SUM(AH11:AK11) -> 0 | BU11: =SUM(M11:P11,V11:Z11,AC11:AE11,AH11:AV11) -> 71.91 | BV11: =I11*J11 -> 129.225 | BX11: =SUM(M11:S11,V11:AV11,BF11:BF11) -> 235.42
B12: Flat 05 | C12: 0 | D12: N | E12: End | F12: GF | G12: 1 | I12: =SUM(AC12:AF12) -> 91.58 | J12: 2.5 | K12: =SUMIFS('Pasted Areas'!$E:$E,'Pasted Areas'!$K:$K,B12,'Pasted Areas'!$C:$C,"*Living*") -> 32.7 | M12: =SUMIFS('Pasted Areas'!$E:$E,'Pasted Areas'!$K:$K,$B12,'Pasted Areas'!$C:$C,"*External Wall Area 1*") -> 69.64 | N12: =SUMIFS('Pasted Areas'!$E:$E,'Pasted Areas'!$K:$K,$B12,'Pasted Areas'!$C:$C,"*External Wall Area 2*") -> 0 | O12: =SUMIFS('Pasted Areas'!$E:$E,'Pasted Areas'!$K:$K,$B12,'Pasted Areas'!$C:$C,"*External Wall Area 3*") -> 0 | P12: =SUMIFS('Pasted Areas'!$E:$E,'Pasted Areas'!$K:$K,$B12,'Pasted Areas'!$C:$C,"*External Wall Area 4*") -> 0 | Q12: =SUMIFS('Pasted Areas'!$E:$E,'Pasted Areas'!$K:$K,$B12,'Pasted Areas'!$C:$C,"*Party Walls to Corridors*") -> 4.16 | R12: =SUMIFS('Pasted Areas'!$E:$E,'Pasted Areas'!$K:$K,$B12,'Pasted Areas'!$C:$C,"*Party Walls to Dwelling*") -> 61.8 | S12: =SUMIFS('Pasted Areas'!$E:$E,'Pasted Areas'!$K:$K,$B12,'Pasted Areas'!$C:$C,"*Internal Partitions*") -> 75.78 | T12: =S12*2 -> 151.56 | V12: =SUMIFS('Pasted Areas'!$E:$E,'Pasted Areas'!$K:$K,$B12,'Pasted Areas'!$C:$C,"*SAP Roof 1*") -> 0 | W12: =SUMIFS('Pasted Areas'!$E:$E,'Pasted Areas'!$K:$K,$B12,'Pasted Areas'!$C:$C,"*SAP Roof 2*") -> 0 | X12: =SUMIFS('Pasted Areas'!$E:$E,'Pasted Areas'!$K:$K,$B12,'Pasted Areas'!$C:$C,"*SAP Roof 3*") -> 0 | Y12: =SUMIFS('Pasted Areas'!$E:$E,'Pasted Areas'!$K:$K,$B12,'Pasted Areas'!$C:$C,"*SAP Roof 4*") -> 0 | Z12: =SUMIFS('Pasted Areas'!$E:$E,'Pasted Areas'!$K:$K,$B12,'Pasted Areas'!$C:$C,"*SAP Roof 5*") -> 0 | AA12: =SUMIFS('Pasted Areas'!$E:$E,'Pasted Areas'!$K:$K,$B12,'Pasted Areas'!$C:$C,"*Party Ceiling*") -> 91.57 | AC12: =SUMIFS('Pasted Areas'!$E:$E,'Pasted Areas'!$K:$K,$B12,'Pasted Areas'!$C:$C,"*Ground Floor*") -> 91.58 | AD12: =SUMIFS('Pasted Areas'!$E:$E,'Pasted Areas'!$K:$K,$B12,'Pasted Areas'!$C:$C,"* Exposed Floor*") -> 0 | AE12: =SUMIFS('Pasted Areas'!$E:$E,'Pasted Areas'!$K:$K,$B12,'Pasted Areas'!$C:$C,"*Semi-Exposed Floor*") -> 0 | AF12: =SUMIFS('Pasted Areas'!$E:$E,'Pasted Areas'!$K:$K,$B12,'Pasted Areas'!$C:$C,"*Party Floor*") -> 0 | AH12: =SUMIFS('Pasted Areas'!$E:$E,'Pasted Areas'!$K:$K,$B12,'Pasted Areas'!$C:$C,"*Front Door*",'Pasted Areas'!$H:$H,AH$7) -> 0 | AI12: =SUMIFS('Pasted Areas'!$E:$E,'Pasted Areas'!$K:$K,$B12,'Pasted Areas'!$C:$C,"*Front Door*",'Pasted Areas'!$H:$H,AI$7) -> 0 | AJ12: =SUMIFS('Pasted Areas'!$E:$E,'Pasted Areas'!$K:$K,$B12,'Pasted Areas'!$C:$C,"*Front Door*",'Pasted Areas'!$H:$H,AJ$7) -> 0 | AK12: =SUMIFS('Pasted Areas'!$E:$E,'Pasted Areas'!$K:$K,$B12,'Pasted Areas'!$C:$C,"*Front Door*",'Pasted Areas'!$H:$H,AK$7) -> 0 | AM12: =SUMIFS('Pasted Areas'!$E:$E,'Pasted Areas'!$K:$K,$B12,'Pasted Areas'!$C:$C,"*Glazing*",'Pasted Areas'!$H:$H,AM$7) -> 0 | AN12: =SUMIFS('Pasted Areas'!$E:$E,'Pasted Areas'!$K:$K,$B12,'Pasted Areas'!$C:$C,"*Glazing*",'Pasted Areas'!$H:$H,AN$7) -> 0 | AO12: =SUMIFS('Pasted Areas'!$E:$E,'Pasted Areas'!$K:$K,$B12,'Pasted Areas'!$C:$C,"*Glazing*",'Pasted Areas'!$H:$H,AO$7) -> 3.6 | AP12: =SUMIFS('Pasted Areas'!$E:$E,'Pasted Areas'!$K:$K,$B12,'Pasted Areas'!$C:$C,"*Glazing*",'Pasted Areas'!$H:$H,AP$7) -> 0 | AQ12: =SUMIFS('Pasted Areas'!$E:$E,'Pasted Areas'!$K:$K,$B12,'Pasted Areas'!$C:$C,"*Glazing*",'Pasted Areas'!$H:$H,AQ$7) -> 1.44 | AR12: =SUMIFS('Pasted Areas'!$E:$E,'Pasted Areas'!$K:$K,$B12,'Pasted Areas'!$C:$C,"*Glazing*",'Pasted Areas'!$H:$H,AR$7) -> 0 | AS12: =SUMIFS('Pasted Areas'!$E:$E,'Pasted Areas'!$K:$K,$B12,'Pasted Areas'!$C:$C,"*Glazing*",'Pasted Areas'!$H:$H,AS$7) -> 5.24 | AT12: =SUMIFS('Pasted Areas'!$E:$E,'Pasted Areas'!$K:$K,$B12,'Pasted Areas'!$C:$C,"*Glazing*",'Pasted Areas'!$H:$H,AT$7) -> 0 | AV12: =SUMIFS('Pasted Areas'!$E:$E,'Pasted Areas'!$K:$K,$B12,'Pasted Areas'!$C:$C,"*Roof Light*") -> 0 | AX12: 2 | AY12: 0 | AZ12: 1 | BA12: 0 | BB12: 1 | BC12: =AX12+AY12 -> 2 | BD12: =AZ12+BA12 -> 1 | BE12: =AZ12+BB12 -> 2 | BF12: =SUMIFS('Pasted Areas'!$E:$E,'Pasted Areas'!$K:$K,$B12,'Pasted Areas'!$C:$C,"*Cooling Area*") -> 0 | BS12: =SUM(AM12:AT12) -> 10.28 | BT12: =SUM(AH12:AK12) -> 0 | BU12: =SUM(M12:P12,V12:Z12,AC12:AE12,AH12:AV12) -> 171.5 | BV12: =I12*J12 -> 228.95 | BX12: =SUM(M12:S12,V12:AV12,BF12:BF12) -> 404.81
B13: Flat 06 | C13: 0 | D13: E | E13: Mid | F13: GF | G13: 3 | I13: =SUM(AC13:AF13) -> 71.95 | J13: 2.5 | K13: =SUMIFS('Pasted Areas'!$E:$E,'Pasted Areas'!$K:$K,B13,'Pasted Areas'!$C:$C,"*Living*") -> 24.56 | M13: =SUMIFS('Pasted Areas'!$E:$E,'Pasted Areas'!$K:$K,$B13,'Pasted Areas'!$C:$C,"*External Wall Area 1*") -> 27.45 | N13: =SUMIFS('Pasted Areas'!$E:$E,'Pasted Areas'!$K:$K,$B13,'Pasted Areas'!$C:$C,"*External Wall Area 2*") -> 0 | O13: =SUMIFS('Pasted Areas'!$E:$E,'Pasted Areas'!$K:$K,$B13,'Pasted Areas'!$C:$C,"*External Wall Area 3*") -> 0 | P13: =SUMIFS('Pasted Areas'!$E:$E,'Pasted Areas'!$K:$K,$B13,'Pasted Areas'!$C:$C,"*External Wall Area 4*") -> 0 | Q13: =SUMIFS('Pasted Areas'!$E:$E,'Pasted Areas'!$K:$K,$B13,'Pasted Areas'!$C:$C,"*Party Walls to Corridors*") -> 32.75 | R13: =SUMIFS('Pasted Areas'!$E:$E,'Pasted Areas'!$K:$K,$B13,'Pasted Areas'!$C:$C,"*Party Walls to Dwelling*") -> 36.69 | S13: =SUMIFS('Pasted Areas'!$E:$E,'Pasted Areas'!$K:$K,$B13,'Pasted Areas'!$C:$C,"*Internal Partitions*") -> 67.11 | T13: =S13*2 -> 134.22 | V13: =SUMIFS('Pasted Areas'!$E:$E,'Pasted Areas'!$K:$K,$B13,'Pasted Areas'!$C:$C,"*SAP Roof 1*") -> 0 | W13: =SUMIFS('Pasted Areas'!$E:$E,'Pasted Areas'!$K:$K,$B13,'Pasted Areas'!$C:$C,"*SAP Roof 2*") -> 0 | X13: =SUMIFS('Pasted Areas'!$E:$E,'Pasted Areas'!$K:$K,$B13,'Pasted Areas'!$C:$C,"*SAP Roof 3*") -> 0 | Y13: =SUMIFS('Pasted Areas'!$E:$E,'Pasted Areas'!$K:$K,$B13,'Pasted Areas'!$C:$C,"*SAP Roof 4*") -> 0 | Z13: =SUMIFS('Pasted Areas'!$E:$E,'Pasted Areas'!$K:$K,$B13,'Pasted Areas'!$C:$C,"*SAP Roof 5*") -> 0 | AA13: =SUMIFS('Pasted Areas'!$E:$E,'Pasted Areas'!$K:$K,$B13,'Pasted Areas'!$C:$C,"*Party Ceiling*") -> 71.95 | AC13: =SUMIFS('Pasted Areas'!$E:$E,'Pasted Areas'!$K:$K,$B13,'Pasted Areas'!$C:$C,"*Ground Floor*") -> 71.95 | AD13: =SUMIFS('Pasted Areas'!$E:$E,'Pasted Areas'!$K:$K,$B13,'Pasted Areas'!$C:$C,"* Exposed Floor*") -> 0 | AE13: =SUMIFS('Pasted Areas'!$E:$E,'Pasted Areas'!$K:$K,$B13,'Pasted Areas'!$C:$C,"*Semi-Exposed Floor*") -> 0 | AF13: =SUMIFS('Pasted Areas'!$E:$E,'Pasted Areas'!$K:$K,$B13,'Pasted Areas'!$C:$C,"*Party Floor*") -> 0 | AH13: =SUMIFS('Pasted Areas'!$E:$E,'Pasted Areas'!$K:$K,$B13,'Pasted Areas'!$C:$C,"*Front Door*",'Pasted Areas'!$H:$H,AH$7) -> 0 | AI13: =SUMIFS('Pasted Areas'!$E:$E,'Pasted Areas'!$K:$K,$B13,'Pasted Areas'!$C:$C,"*Front Door*",'Pasted Areas'!$H:$H,AI$7) -> 0 | AJ13: =SUMIFS('Pasted Areas'!$E:$E,'Pasted Areas'!$K:$K,$B13,'Pasted Areas'!$C:$C,"*Front Door*",'Pasted Areas'!$H:$H,AJ$7) -> 0 | AK13: =SUMIFS('Pasted Areas'!$E:$E,'Pasted Areas'!$K:$K,$B13,'Pasted Areas'!$C:$C,"*Front Door*",'Pasted Areas'!$H:$H,AK$7) -> 0 | AM13: =SUMIFS('Pasted Areas'!$E:$E,'Pasted Areas'!$K:$K,$B13,'Pasted Areas'!$C:$C,"*Glazing*",'Pasted Areas'!$H:$H,AM$7) -> 0 | AN13: =SUMIFS('Pasted Areas'!$E:$E,'Pasted Areas'!$K:$K,$B13,'Pasted Areas'!$C:$C,"*Glazing*",'Pasted Areas'!$H:$H,AN$7) -> 0 | AO13: =SUMIFS('Pasted Areas'!$E:$E,'Pasted Areas'!$K:$K,$B13,'Pasted Areas'!$C:$C,"*Glazing*",'Pasted Areas'!$H:$H,AO$7) -> 0 | AP13: =SUMIFS('Pasted Areas'!$E:$E,'Pasted Areas'!$K:$K,$B13,'Pasted Areas'!$C:$C,"*Glazing*",'Pasted Areas'!$H:$H,AP$7) -> 0 | AQ13: =SUMIFS('Pasted Areas'!$E:$E,'Pasted Areas'!$K:$K,$B13,'Pasted Areas'!$C:$C,"*Glazing*",'Pasted Areas'!$H:$H,AQ$7) -> 0 | AR13: =SUMIFS('Pasted Areas'!$E:$E,'Pasted Areas'!$K:$K,$B13,'Pasted Areas'!$C:$C,"*Glazing*",'Pasted Areas'!$H:$H,AR$7) -> 0 | AS13: =SUMIFS('Pasted Areas'!$E:$E,'Pasted Areas'!$K:$K,$B13,'Pasted Areas'!$C:$C,"*Glazing*",'Pasted Areas'!$H:$H,AS$7) -> 8.84 | AT13: =SUMIFS('Pasted Areas'!$E:$E,'Pasted Areas'!$K:$K,$B13,'Pasted Areas'!$C:$C,"*Glazing*",'Pasted Areas'!$H:$H,AT$7) -> 0 | AV13: =SUMIFS('Pasted Areas'!$E:$E,'Pasted Areas'!$K:$K,$B13,'Pasted Areas'!$C:$C,"*Roof Light*") -> 0 | AX13: 2 | AY13: 0 | AZ13: 1 | BA13: 0 | BB13: 1 | BC13: =AX13+AY13 -> 2 | BD13: =AZ13+BA13 -> 1 | BE13: =AZ13+BB13 -> 2 | BF13: =SUMIFS('Pasted Areas'!$E:$E,'Pasted Areas'!$K:$K,$B13,'Pasted Areas'!$C:$C,"*Cooling Area*") -> 0 | BS13: =SUM(AM13:AT13) -> 8.84 | BT13: =SUM(AH13:AK13) -> 0 | BU13: =SUM(M13:P13,V13:Z13,AC13:AE13,AH13:AV13) -> 108.24 | BV13: =I13*J13 -> 179.875 | BX13: =SUM(M13:S13,V13:AV13,BF13:BF13) -> 316.74
B14: Flat 07 | C14: 1 | D14: SE | E14: End | F14: Mid | G14: 2 | I14: =SUM(AC14:AF14) -> 71.69 | J14: 2.5 | K14: =SUMIFS('Pasted Areas'!$E:$E,'Pasted Areas'!$K:$K,B14,'Pasted Areas'!$C:$C,"*Living*") -> 25.64 | M14: =SUMIFS('Pasted Areas'!$E:$E,'Pasted Areas'!$K:$K,$B14,'Pasted Areas'!$C:$C,"*External Wall Area 1*") -> 40.28 | N14: =SUMIFS('Pasted Areas'!$E:$E,'Pasted Areas'!$K:$K,$B14,'Pasted Areas'!$C:$C,"*External Wall Area 2*") -> 0 | O14: =SUMIFS('Pasted Areas'!$E:$E,'Pasted Areas'!$K:$K,$B14,'Pasted Areas'!$C:$C,"*External Wall Area 3*") -> 0 | P14: =SUMIFS('Pasted Areas'!$E:$E,'Pasted Areas'!$K:$K,$B14,'Pasted Areas'!$C:$C,"*External Wall Area 4*") -> 0 | Q14: =SUMIFS('Pasted Areas'!$E:$E,'Pasted Areas'!$K:$K,$B14,'Pasted Areas'!$C:$C,"*Party Walls to Corridors*") -> 19.29 | R14: =SUMIFS('Pasted Areas'!$E:$E,'Pasted Areas'!$K:$K,$B14,'Pasted Areas'!$C:$C,"*Party Walls to Dwelling*") -> 26.18 | S14: =SUMIFS('Pasted Areas'!$E:$E,'Pasted Areas'!$K:$K,$B14,'Pasted Areas'!$C:$C,"*Internal Partitions*") -> 73.51 | T14: =S14*2 -> 147.02 | V14: =SUMIFS('Pasted Areas'!$E:$E,'Pasted Areas'!$K:$K,$B14,'Pasted Areas'!$C:$C,"*SAP Roof 1*") -> 0 | W14: =SUMIFS('Pasted Areas'!$E:$E,'Pasted Areas'!$K:$K,$B14,'Pasted Areas'!$C:$C,"*SAP Roof 2*") -> 0 | X14: =SUMIFS('Pasted Areas'!$E:$E,'Pasted Areas'!$K:$K,$B14,'Pasted Areas'!$C:$C,"*SAP Roof 3*") -> 0 | Y14: =SUMIFS('Pasted Areas'!$E:$E,'Pasted Areas'!$K:$K,$B14,'Pasted Areas'!$C:$C,"*SAP Roof 4*") -> 0 | Z14: =SUMIFS('Pasted Areas'!$E:$E,'Pasted Areas'!$K:$K,$B14,'Pasted Areas'!$C:$C,"*SAP Roof 5*") -> 0 | AA14: =SUMIFS('Pasted Areas'!$E:$E,'Pasted Areas'!$K:$K,$B14,'Pasted Areas'!$C:$C,"*Party Ceiling*") -> 71.69 | AC14: =SUMIFS('Pasted Areas'!$E:$E,'Pasted Areas'!$K:$K,$B14,'Pasted Areas'!$C:$C,"*Ground Floor*") -> 0 | AD14: =SUMIFS('Pasted Areas'!$E:$E,'Pasted Areas'!$K:$K,$B14,'Pasted Areas'!$C:$C,"* Exposed Floor*") -> 2.91 | AE14: =SUMIFS('Pasted Areas'!$E:$E,'Pasted Areas'!$K:$K,$B14,'Pasted Areas'!$C:$C,"*Semi-Exposed Floor*") -> 3.96 | AF14: =SUMIFS('Pasted Areas'!$E:$E,'Pasted Areas'!$K:$K,$B14,'Pasted Areas'!$C:$C,"*Party Floor*") -> 64.82 | AH14: =SUMIFS('Pasted Areas'!$E:$E,'Pasted Areas'!$K:$K,$B14,'Pasted Areas'!$C:$C,"*Front Door*",'Pasted Areas'!$H:$H,AH$7) -> 0 | AI14: =SUMIFS('Pasted Areas'!$E:$E,'Pasted Areas'!$K:$K,$B14,'Pasted Areas'!$C:$C,"*Front Door*",'Pasted Areas'!$H:$H,AI$7) -> 0 | AJ14: =SUMIFS('Pasted Areas'!$E:$E,'Pasted Areas'!$K:$K,$B14,'Pasted Areas'!$C:$C,"*Front Door*",'Pasted Areas'!$H:$H,AJ$7) -> 0 | AK14: =SUMIFS('Pasted Areas'!$E:$E,'Pasted Areas'!$K:$K,$B14,'Pasted Areas'!$C:$C,"*Front Door*",'Pasted Areas'!$H:$H,AK$7) -> 0 | AM14: =SUMIFS('Pasted Areas'!$E:$E,'Pasted Areas'!$K:$K,$B14,'Pasted Areas'!$C:$C,"*Glazing*",'Pasted Areas'!$H:$H,AM$7) -> 0 | AN14: =SUMIFS('Pasted Areas'!$E:$E,'Pasted Areas'!$K:$K,$B14,'Pasted Areas'!$C:$C,"*Glazing*",'Pasted Areas'!$H:$H,AN$7) -> 0 | AO14: =SUMIFS('Pasted Areas'!$E:$E,'Pasted Areas'!$K:$K,$B14,'Pasted Areas'!$C:$C,"*Glazing*",'Pasted Areas'!$H:$H,AO$7) -> 0 | AP14: =SUMIFS('Pasted Areas'!$E:$E,'Pasted Areas'!$K:$K,$B14,'Pasted Areas'!$C:$C,"*Glazing*",'Pasted Areas'!$H:$H,AP$7) -> 2.12 | AQ14: =SUMIFS('Pasted Areas'!$E:$E,'Pasted Areas'!$K:$K,$B14,'Pasted Areas'!$C:$C,"*Glazing*",'Pasted Areas'!$H:$H,AQ$7) -> 0 | AR14: =SUMIFS('Pasted Areas'!$E:$E,'Pasted Areas'!$K:$K,$B14,'Pasted Areas'!$C:$C,"*Glazing*",'Pasted Areas'!$H:$H,AR$7) -> 7.05 | AS14: =SUMIFS('Pasted Areas'!$E:$E,'Pasted Areas'!$K:$K,$B14,'Pasted Areas'!$C:$C,"*Glazing*",'Pasted Areas'!$H:$H,AS$7) -> 0 | AT14: =SUMIFS('Pasted Areas'!$E:$E,'Pasted Areas'!$K:$K,$B14,'Pasted Areas'!$C:$C,"*Glazing*",'Pasted Areas'!$H:$H,AT$7) -> 5.4 | AV14: =SUMIFS('Pasted Areas'!$E:$E,'Pasted Areas'!$K:$K,$B14,'Pasted Areas'!$C:$C,"*Roof Light*") -> 0 | AX14: 2 | AY14: 0 | AZ14: 1 | BA14: 0 | BB14: 1 | BC14: =AX14+AY14 -> 2 | BD14: =AZ14+BA14 -> 1 | BE14: =AZ14+BB14 -> 2 | BF14: =SUMIFS('Pasted Areas'!$E:$E,'Pasted Areas'!$K:$K,$B14,'Pasted Areas'!$C:$C,"*Cooling Area*") -> 0 | BS14: =SUM(AM14:AT14) -> 14.57 | BT14: =SUM(AH14:AK14) -> 0 | BU14: =SUM(M14:P14,V14:Z14,AC14:AE14,AH14:AV14) -> 61.72 | BV14: =I14*J14 -> 179.225 | BX14: =SUM(M14:S14,V14:AV14,BF14:BF14) -> 317.21
B15: Flat 08 | C15: 1 | D15: SW | E15: End | F15: Mid | G15: 2 | I15: =SUM(AC15:AF15) -> 72.97 | J15: 2.5 | K15: =SUMIFS('Pasted Areas'!$E:$E,'Pasted Areas'!$K:$K,B15,'Pasted Areas'!$C:$C,"*Living*") -> 25.67 | M15: =SUMIFS('Pasted Areas'!$E:$E,'Pasted Areas'!$K:$K,$B15,'Pasted Areas'!$C:$C,"*External Wall Area 1*") -> 36.93 | N15: =SUMIFS('Pasted Areas'!$E:$E,'Pasted Areas'!$K:$K,$B15,'Pasted Areas'!$C:$C,"*External Wall Area 2*") -> 0 | O15: =SUMIFS('Pasted Areas'!$E:$E,'Pasted Areas'!$K:$K,$B15,'Pasted Areas'!$C:$C,"*External Wall Area 3*") -> 0 | P15: =SUMIFS('Pasted Areas'!$E:$E,'Pasted Areas'!$K:$K,$B15,'Pasted Areas'!$C:$C,"*External Wall Area 4*") -> 0 | Q15: =SUMIFS('Pasted Areas'!$E:$E,'Pasted Areas'!$K:$K,$B15,'Pasted Areas'!$C:$C,"*Party Walls to Corridors*") -> 7.99 | R15: =SUMIFS('Pasted Areas'!$E:$E,'Pasted Areas'!$K:$K,$B15,'Pasted Areas'!$C:$C,"*Party Walls to Dwelling*") -> 40.67 | S15: =SUMIFS('Pasted Areas'!$E:$E,'Pasted Areas'!$K:$K,$B15,'Pasted Areas'!$C:$C,"*Internal Partitions*") -> 82.97 | T15: =S15*2 -> 165.94 | V15: =SUMIFS('Pasted Areas'!$E:$E,'Pasted Areas'!$K:$K,$B15,'Pasted Areas'!$C:$C,"*SAP Roof 1*") -> 0 | W15: =SUMIFS('Pasted Areas'!$E:$E,'Pasted Areas'!$K:$K,$B15,'Pasted Areas'!$C:$C,"*SAP Roof 2*") -> 0 | X15: =SUMIFS('Pasted Areas'!$E:$E,'Pasted Areas'!$K:$K,$B15,'Pasted Areas'!$C:$C,"*SAP Roof 3*") -> 0 | Y15: =SUMIFS('Pasted Areas'!$E:$E,'Pasted Areas'!$K:$K,$B15,'Pasted Areas'!$C:$C,"*SAP Roof 4*") -> 0 | Z15: =SUMIFS('Pasted Areas'!$E:$E,'Pasted Areas'!$K:$K,$B15,'Pasted Areas'!$C:$C,"*SAP Roof 5*") -> 0 | AA15: =SUMIFS('Pasted Areas'!$E:$E,'Pasted Areas'!$K:$K,$B15,'Pasted Areas'!$C:$C,"*Party Ceiling*") -> 72.97 | AC15: =SUMIFS('Pasted Areas'!$E:$E,'Pasted Areas'!$K:$K,$B15,'Pasted Areas'!$C:$C,"*Ground Floor*") -> 0 | AD15: =SUMIFS('Pasted Areas'!$E:$E,'Pasted Areas'!$K:$K,$B15,'Pasted Areas'!$C:$C,"* Exposed Floor*") -> 0 | AE15: =SUMIFS('Pasted Areas'!$E:$E,'Pasted Areas'!$K:$K,$B15,'Pasted Areas'!$C:$C,"*Semi-Exposed Floor*") -> 0 | AF15: =SUMIFS('Pasted Areas'!$E:$E,'Pasted Areas'!$K:$K,$B15,'Pasted Areas'!$C:$C,"*Party Floor*") -> 72.97 | AH15: =SUMIFS('Pasted Areas'!$E:$E,'Pasted Areas'!$K:$K,$B15,'Pasted Areas'!$C:$C,"*Front Door*",'Pasted Areas'!$H:$H,AH$7) -> 0 | AI15: =SUMIFS('Pasted Areas'!$E:$E,'Pasted Areas'!$K:$K,$B15,'Pasted Areas'!$C:$C,"*Front Door*",'Pasted Areas'!$H:$H,AI$7) -> 0 | AJ15: =SUMIFS('Pasted Areas'!$E:$E,'Pasted Areas'!$K:$K,$B15,'Pasted Areas'!$C:$C,"*Front Door*",'Pasted Areas'!$H:$H,AJ$7) -> 0 | AK15: =SUMIFS('Pasted Areas'!$E:$E,'Pasted Areas'!$K:$K,$B15,'Pasted Areas'!$C:$C,"*Front Door*",'Pasted Areas'!$H:$H,AK$7) -> 0 | AM15: =SUMIFS('Pasted Areas'!$E:$E,'Pasted Areas'!$K:$K,$B15,'Pasted Areas'!$C:$C,"*Glazing*",'Pasted Areas'!$H:$H,AM$7) -> 0 | AN15: =SUMIFS('Pasted Areas'!$E:$E,'Pasted Areas'!$K:$K,$B15,'Pasted Areas'!$C:$C,"*Glazing*",'Pasted Areas'!$H:$H,AN$7) -> 2.88 | AO15: =SUMIFS('Pasted Areas'!$E:$E,'Pasted Areas'!$K:$K,$B15,'Pasted Areas'!$C:$C,"*Glazing*",'Pasted Areas'!$H:$H,AO$7) -> 0 | AP15: =SUMIFS('Pasted Areas'!$E:$E,'Pasted Areas'!$K:$K,$B15,'Pasted Areas'!$C:$C,"*Glazing*",'Pasted Areas'!$H:$H,AP$7) -> 0 | AQ15: =SUMIFS('Pasted Areas'!$E:$E,'Pasted Areas'!$K:$K,$B15,'Pasted Areas'!$C:$C,"*Glazing*",'Pasted Areas'!$H:$H,AQ$7) -> 0 | AR15: =SUMIFS('Pasted Areas'!$E:$E,'Pasted Areas'!$K:$K,$B15,'Pasted Areas'!$C:$C,"*Glazing*",'Pasted Areas'!$H:$H,AR$7) -> 0 | AS15: =SUMIFS('Pasted Areas'!$E:$E,'Pasted Areas'!$K:$K,$B15,'Pasted Areas'!$C:$C,"*Glazing*",'Pasted Areas'!$H:$H,AS$7) -> 0 | AT15: =SUMIFS('Pasted Areas'!$E:$E,'Pasted Areas'!$K:$K,$B15,'Pasted Areas'!$C:$C,"*Glazing*",'Pasted Areas'!$H:$H,AT$7) -> 8.84 | AV15: =SUMIFS('Pasted Areas'!$E:$E,'Pasted Areas'!$K:$K,$B15,'Pasted Areas'!$C:$C,"*Roof Light*") -> 0 | AX15: 2 | AY15: 0 | AZ15: 1 | BA15: 0 | BB15: 1 | BC15: =AX15+AY15 -> 2 | BD15: =AZ15+BA15 -> 1 | BE15: =AZ15+BB15 -> 2 | BF15: =SUMIFS('Pasted Areas'!$E:$E,'Pasted Areas'!$K:$K,$B15,'Pasted Areas'!$C:$C,"*Cooling Area*") -> 0 | BS15: =SUM(AM15:AT15) -> 11.72 | BT15: =SUM(AH15:AK15) -> 0 | BU15: =SUM(M15:P15,V15:Z15,AC15:AE15,AH15:AV15) -> 48.65 | BV15: =I15*J15 -> 182.425 | BX15: =SUM(M15:S15,V15:AV15,BF15:BF15) -> 326.22
B16: Flat 09 | C16: 1 | D16: W | E16: Mid | F16: Mid | G16: 3 | I16: =SUM(AC16:AF16) -> 65.52 | J16: 2.5 | K16: =SUMIFS('Pasted Areas'!$E:$E,'Pasted Areas'!$K:$K,B16,'Pasted Areas'!$C:$C,"*Living*") -> 25.73 | M16: =SUMIFS('Pasted Areas'!$E:$E,'Pasted Areas'!$K:$K,$B16,'Pasted Areas'!$C:$C,"*External Wall Area 1*") -> 26.04 | N16: =SUMIFS('Pasted Areas'!$E:$E,'Pasted Areas'!$K:$K,$B16,'Pasted Areas'!$C:$C,"*External Wall Area 2*") -> 0 | O16: =SUMIFS('Pasted Areas'!$E:$E,'Pasted Areas'!$K:$K,$B16,'Pasted Areas'!$C:$C,"*External Wall Area 3*") -> 0 | P16: =SUMIFS('Pasted Areas'!$E:$E,'Pasted Areas'!$K:$K,$B16,'Pasted Areas'!$C:$C,"*External Wall Area 4*") -> 0 | Q16: =SUMIFS('Pasted Areas'!$E:$E,'Pasted Areas'!$K:$K,$B16,'Pasted Areas'!$C:$C,"*Party Walls to Corridors*") -> 24.12 | R16: =SUMIFS('Pasted Areas'!$E:$E,'Pasted Areas'!$K:$K,$B16,'Pasted Areas'!$C:$C,"*Party Walls to Dwelling*") -> 42.99 | S16: =SUMIFS('Pasted Areas'!$E:$E,'Pasted Areas'!$K:$K,$B16,'Pasted Areas'!$C:$C,"*Internal Partitions*") -> 61.95 | T16: =S16*2 -> 123.9 | V16: =SUMIFS('Pasted Areas'!$E:$E,'Pasted Areas'!$K:$K,$B16,'Pasted Areas'!$C:$C,"*SAP Roof 1*") -> 0 | W16: =SUMIFS('Pasted Areas'!$E:$E,'Pasted Areas'!$K:$K,$B16,'Pasted Areas'!$C:$C,"*SAP Roof 2*") -> 0 | X16: =SUMIFS('Pasted Areas'!$E:$E,'Pasted Areas'!$K:$K,$B16,'Pasted Areas'!$C:$C,"*SAP Roof 3*") -> 0 | Y16: =SUMIFS('Pasted Areas'!$E:$E,'Pasted Areas'!$K:$K,$B16,'Pasted Areas'!$C:$C,"*SAP Roof 4*") -> 0 | Z16: =SUMIFS('Pasted Areas'!$E:$E,'Pasted Areas'!$K:$K,$B16,'Pasted Areas'!$C:$C,"*SAP Roof 5*") -> 0 | AA16: =SUMIFS('Pasted Areas'!$E:$E,'Pasted Areas'!$K:$K,$B16,'Pasted Areas'!$C:$C,"*Party Ceiling*") -> 65.52 | AC16: =SUMIFS('Pasted Areas'!$E:$E,'Pasted Areas'!$K:$K,$B16,'Pasted Areas'!$C:$C,"*Ground Floor*") -> 0 | AD16: =SUMIFS('Pasted Areas'!$E:$E,'Pasted Areas'!$K:$K,$B16,'Pasted Areas'!$C:$C,"* Exposed Floor*") -> 0 | AE16: =SUMIFS('Pasted Areas'!$E:$E,'Pasted Areas'!$K:$K,$B16,'Pasted Areas'!$C:$C,"*Semi-Exposed Floor*") -> 0 | AF16: =SUMIFS('Pasted Areas'!$E:$E,'Pasted Areas'!$K:$K,$B16,'Pasted Areas'!$C:$C,"*Party Floor*") -> 65.52 | AH16: =SUMIFS('Pasted Areas'!$E:$E,'Pasted Areas'!$K:$K,$B16,'Pasted Areas'!$C:$C,"*Front Door*",'Pasted Areas'!$H:$H,AH$7) -> 0 | AI16: =SUMIFS('Pasted Areas'!$E:$E,'Pasted Areas'!$K:$K,$B16,'Pasted Areas'!$C:$C,"*Front Door*",'Pasted Areas'!$H:$H,AI$7) -> 0 | AJ16: =SUMIFS('Pasted Areas'!$E:$E,'Pasted Areas'!$K:$K,$B16,'Pasted Areas'!$C:$C,"*Front Door*",'Pasted Areas'!$H:$H,AJ$7) -> 0 | AK16: =SUMIFS('Pasted Areas'!$E:$E,'Pasted Areas'!$K:$K,$B16,'Pasted Areas'!$C:$C,"*Front Door*",'Pasted Areas'!$H:$H,AK$7) -> 0 | AM16: =SUMIFS('Pasted Areas'!$E:$E,'Pasted Areas'!$K:$K,$B16,'Pasted Areas'!$C:$C,"*Glazing*",'Pasted Areas'!$H:$H,AM$7) -> 0 | AN16: =SUMIFS('Pasted Areas'!$E:$E,'Pasted Areas'!$K:$K,$B16,'Pasted Areas'!$C:$C,"*Glazing*",'Pasted Areas'!$H:$H,AN$7) -> 1.8 | AO16: =SUMIFS('Pasted Areas'!$E:$E,'Pasted Areas'!$K:$K,$B16,'Pasted Areas'!$C:$C,"*Glazing*",'Pasted Areas'!$H:$H,AO$7) -> 4.68 | AP16: =SUMIFS('Pasted Areas'!$E:$E,'Pasted Areas'!$K:$K,$B16,'Pasted Areas'!$C:$C,"*Glazing*",'Pasted Areas'!$H:$H,AP$7) -> 1.89 | AQ16: =SUMIFS('Pasted Areas'!$E:$E,'Pasted Areas'!$K:$K,$B16,'Pasted Areas'!$C:$C,"*Glazing*",'Pasted Areas'!$H:$H,AQ$7) -> 0 | AR16: =SUMIFS('Pasted Areas'!$E:$E,'Pasted Areas'!$K:$K,$B16,'Pasted Areas'!$C:$C,"*Glazing*",'Pasted Areas'!$H:$H,AR$7) -> 0 | AS16: =SUMIFS('Pasted Areas'!$E:$E,'Pasted Areas'!$K:$K,$B16,'Pasted Areas'!$C:$C,"*Glazing*",'Pasted Areas'!$H:$H,AS$7) -> 0 | AT16: =SUMIFS('Pasted Areas'!$E:$E,'Pasted Areas'!$K:$K,$B16,'Pasted Areas'!$C:$C,"*Glazing*",'Pasted Areas'!$H:$H,AT$7) -> 0 | AV16: =SUMIFS('Pasted Areas'!$E:$E,'Pasted Areas'!$K:$K,$B16,'Pasted Areas'!$C:$C,"*Roof Light*") -> 0 | AX16: 1 | AY16: 0 | AZ16: 1 | BA16: 0 | BB16: 0 | BC16: =AX16+AY16 -> 1 | BD16: =AZ16+BA16 -> 1 | BE16: =AZ16+BB16 -> 1 | BF16: =SUMIFS('Pasted Areas'!$E:$E,'Pasted Areas'!$K:$K,$B16,'Pasted Areas'!$C:$C,"*Cooling Area*") -> 0 | BS16: =SUM(AM16:AT16) -> 8.37 | BT16: =SUM(AH16:AK16) -> 0 | BU16: =SUM(M16:P16,V16:Z16,AC16:AE16,AH16:AV16) -> 34.41 | BV16: =I16*J16 -> 163.8 | BX16: =SUM(M16:S16,V16:AV16,BF16:BF16) -> 294.51
B17: Flat 10 | C17: 1 | D17: W | E17: Mid | F17: Mid | G17: 3 | I17: =SUM(AC17:AF17) -> 51.68 | J17: 2.5 | K17: =SUMIFS('Pasted Areas'!$E:$E,'Pasted Areas'!$K:$K,B17,'Pasted Areas'!$C:$C,"*Living*") -> 23.6 | M17: =SUMIFS('Pasted Areas'!$E:$E,'Pasted Areas'!$K:$K,$B17,'Pasted Areas'!$C:$C,"*External Wall Area 1*") -> 13.18 | N17: =SUMIFS('Pasted Areas'!$E:$E,'Pasted Areas'!$K:$K,$B17,'Pasted Areas'!$C:$C,"*External Wall Area 2*") -> 0 | O17: =SUMIFS('Pasted Areas'!$E:$E,'Pasted Areas'!$K:$K,$B17,'Pasted Areas'!$C:$C,"*External Wall Area 3*") -> 0 | P17: =SUMIFS('Pasted Areas'!$E:$E,'Pasted Areas'!$K:$K,$B17,'Pasted Areas'!$C:$C,"*External Wall Area 4*") -> 0 | Q17: =SUMIFS('Pasted Areas'!$E:$E,'Pasted Areas'!$K:$K,$B17,'Pasted Areas'!$C:$C,"*Party Walls to Corridors*") -> 16.76 | R17: =SUMIFS('Pasted Areas'!$E:$E,'Pasted Areas'!$K:$K,$B17,'Pasted Areas'!$C:$C,"*Party Walls to Dwelling*") -> 50.22 | S17: =SUMIFS('Pasted Areas'!$E:$E,'Pasted Areas'!$K:$K,$B17,'Pasted Areas'!$C:$C,"*Internal Partitions*") -> 44.76 | T17: =S17*2 -> 89.52 | V17: =SUMIFS('Pasted Areas'!$E:$E,'Pasted Areas'!$K:$K,$B17,'Pasted Areas'!$C:$C,"*SAP Roof 1*") -> 0 | W17: =SUMIFS('Pasted Areas'!$E:$E,'Pasted Areas'!$K:$K,$B17,'Pasted Areas'!$C:$C,"*SAP Roof 2*") -> 0 | X17: =SUMIFS('Pasted Areas'!$E:$E,'Pasted Areas'!$K:$K,$B17,'Pasted Areas'!$C:$C,"*SAP Roof 3*") -> 0 | Y17: =SUMIFS('Pasted Areas'!$E:$E,'Pasted Areas'!$K:$K,$B17,'Pasted Areas'!$C:$C,"*SAP Roof 4*") -> 0 | Z17: =SUMIFS('Pasted Areas'!$E:$E,'Pasted Areas'!$K:$K,$B17,'Pasted Areas'!$C:$C,"*SAP Roof 5*") -> 0 | AA17: =SUMIFS('Pasted Areas'!$E:$E,'Pasted Areas'!$K:$K,$B17,'Pasted Areas'!$C:$C,"*Party Ceiling*") -> 51.69 | AC17: =SUMIFS('Pasted Areas'!$E:$E,'Pasted Areas'!$K:$K,$B17,'Pasted Areas'!$C:$C,"*Ground Floor*") -> 0 | AD17: =SUMIFS('Pasted Areas'!$E:$E,'Pasted Areas'!$K:$K,$B17,'Pasted Areas'!$C:$C,"* Exposed Floor*") -> 0 | AE17: =SUMIFS('Pasted Areas'!$E:$E,'Pasted Areas'!$K:$K,$B17,'Pasted Areas'!$C:$C,"*Semi-Exposed Floor*") -> 0 | AF17: =SUMIFS('Pasted Areas'!$E:$E,'Pasted Areas'!$K:$K,$B17,'Pasted Areas'!$C:$C,"*Party Floor*") -> 51.68 | AH17: =SUMIFS('Pasted Areas'!$E:$E,'Pasted Areas'!$K:$K,$B17,'Pasted Areas'!$C:$C,"*Front Door*",'Pasted Areas'!$H:$H,AH$7) -> 0 | AI17: =SUMIFS('Pasted Areas'!$E:$E,'Pasted Areas'!$K:$K,$B17,'Pasted Areas'!$C:$C,"*Front Door*",'Pasted Areas'!$H:$H,AI$7) -> 0 | AJ17: =SUMIFS('Pasted Areas'!$E:$E,'Pasted Areas'!$K:$K,$B17,'Pasted Areas'!$C:$C,"*Front Door*",'Pasted Areas'!$H:$H,AJ$7) -> 0 | AK17: =SUMIFS('Pasted Areas'!$E:$E,'Pasted Areas'!$K:$K,$B17,'Pasted Areas'!$C:$C,"*Front Door*",'Pasted Areas'!$H:$H,AK$7) -> 0 | AM17: =SUMIFS('Pasted Areas'!$E:$E,'Pasted Areas'!$K:$K,$B17,'Pasted Areas'!$C:$C,"*Glazing*",'Pasted Areas'!$H:$H,AM$7) -> 0 | AN17: =SUMIFS('Pasted Areas'!$E:$E,'Pasted Areas'!$K:$K,$B17,'Pasted Areas'!$C:$C,"*Glazing*",'Pasted Areas'!$H:$H,AN$7) -> 0 | AO17: =SUMIFS('Pasted Areas'!$E:$E,'Pasted Areas'!$K:$K,$B17,'Pasted Areas'!$C:$C,"*Glazing*",'Pasted Areas'!$H:$H,AO$7) -> 7.04 | AP17: =SUMIFS('Pasted Areas'!$E:$E,'Pasted Areas'!$K:$K,$B17,'Pasted Areas'!$C:$C,"*Glazing*",'Pasted Areas'!$H:$H,AP$7) -> 0 | AQ17: =SUMIFS('Pasted Areas'!$E:$E,'Pasted Areas'!$K:$K,$B17,'Pasted Areas'!$C:$C,"*Glazing*",'Pasted Areas'!$H:$H,AQ$7) -> 0 | AR17: =SUMIFS('Pasted Areas'!$E:$E,'Pasted Areas'!$K:$K,$B17,'Pasted Areas'!$C:$C,"*Glazing*",'Pasted Areas'!$H:$H,AR$7) -> 0 | AS17: =SUMIFS('Pasted Areas'!$E:$E,'Pasted Areas'!$K:$K,$B17,'Pasted Areas'!$C:$C,"*Glazing*",'Pasted Areas'!$H:$H,AS$7) -> 0 | AT17: =SUMIFS('Pasted Areas'!$E:$E,'Pasted Areas'!$K:$K,$B17,'Pasted Areas'!$C:$C,"*Glazing*",'Pasted Areas'!$H:$H,AT$7) -> 0 | AV17: =SUMIFS('Pasted Areas'!$E:$E,'Pasted Areas'!$K:$K,$B17,'Pasted Areas'!$C:$C,"*Roof Light*") -> 0 | AX17: 1 | AY17: 0 | AZ17: 1 | BA17: 0 | BB17: 0 | BC17: =AX17+AY17 -> 1 | BD17: =AZ17+BA17 -> 1 | BE17: =AZ17+BB17 -> 1 | BF17: =SUMIFS('Pasted Areas'!$E:$E,'Pasted Areas'!$K:$K,$B17,'Pasted Areas'!$C:$C,"*Cooling Area*") -> 0 | BS17: =SUM(AM17:AT17) -> 7.04 | BT17: =SUM(AH17:AK17) -> 0 | BU17: =SUM(M17:P17,V17:Z17,AC17:AE17,AH17:AV17) -> 20.22 | BV17: =I17*J17 -> 129.2 | BX17: =SUM(M17:S17,V17:AV17,BF17:BF17) -> 235.33
B18: Flat 11 | C18: 1 | D18: N | E18: End | F18: Mid | G18: 1 | I18: =SUM(AC18:AF18) -> 91.58 | J18: 2.5 | K18: =SUMIFS('Pasted Areas'!$E:$E,'Pasted Areas'!$K:$K,B18,'Pasted Areas'!$C:$C,"*Living*") -> 32.7 | M18: =SUMIFS('Pasted Areas'!$E:$E,'Pasted Areas'!$K:$K,$B18,'Pasted Areas'!$C:$C,"*External Wall Area 1*") -> 69.64 | N18: =SUMIFS('Pasted Areas'!$E:$E,'Pasted Areas'!$K:$K,$B18,'Pasted Areas'!$C:$C,"*External Wall Area 2*") -> 0 | O18: =SUMIFS('Pasted Areas'!$E:$E,'Pasted Areas'!$K:$K,$B18,'Pasted Areas'!$C:$C,"*External Wall Area 3*") -> 0 | P18: =SUMIFS('Pasted Areas'!$E:$E,'Pasted Areas'!$K:$K,$B18,'Pasted Areas'!$C:$C,"*External Wall Area 4*") -> 0 | Q18: =SUMIFS('Pasted Areas'!$E:$E,'Pasted Areas'!$K:$K,$B18,'Pasted Areas'!$C:$C,"*Party Walls to Corridors*") -> 4.16 | R18: =SUMIFS('Pasted Areas'!$E:$E,'Pasted Areas'!$K:$K,$B18,'Pasted Areas'!$C:$C,"*Party Walls to Dwelling*") -> 61.8 | S18: =SUMIFS('Pasted Areas'!$E:$E,'Pasted Areas'!$K:$K,$B18,'Pasted Areas'!$C:$C,"*Internal Partitions*") -> 76.24 | T18: =S18*2 -> 152.48 | V18: =SUMIFS('Pasted Areas'!$E:$E,'Pasted Areas'!$K:$K,$B18,'Pasted Areas'!$C:$C,"*SAP Roof 1*") -> 0 | W18: =SUMIFS('Pasted Areas'!$E:$E,'Pasted Areas'!$K:$K,$B18,'Pasted Areas'!$C:$C,"*SAP Roof 2*") -> 0 | X18: =SUMIFS('Pasted Areas'!$E:$E,'Pasted Areas'!$K:$K,$B18,'Pasted Areas'!$C:$C,"*SAP Roof 3*") -> 0 | Y18: =SUMIFS('Pasted Areas'!$E:$E,'Pasted Areas'!$K:$K,$B18,'Pasted Areas'!$C:$C,"*SAP Roof 4*") -> 0 | Z18: =SUMIFS('Pasted Areas'!$E:$E,'Pasted Areas'!$K:$K,$B18,'Pasted Areas'!$C:$C,"*SAP Roof 5*") -> 0 | AA18: =SUMIFS('Pasted Areas'!$E:$E,'Pasted Areas'!$K:$K,$B18,'Pasted Areas'!$C:$C,"*Party Ceiling*") -> 91.57 | AC18: =SUMIFS('Pasted Areas'!$E:$E,'Pasted Areas'!$K:$K,$B18,'Pasted Areas'!$C:$C,"*Ground Floor*") -> 0 | AD18: =SUMIFS('Pasted Areas'!$E:$E,'Pasted Areas'!$K:$K,$B18,'Pasted Areas'!$C:$C,"* Exposed Floor*") -> 0 | AE18: =SUMIFS('Pasted Areas'!$E:$E,'Pasted Areas'!$K:$K,$B18,'Pasted Areas'!$C:$C,"*Semi-Exposed Floor*") -> 0 | AF18: =SUMIFS('Pasted Areas'!$E:$E,'Pasted Areas'!$K:$K,$B18,'Pasted Areas'!$C:$C,"*Party Floor*") -> 91.58 | AH18: =SUMIFS('Pasted Areas'!$E:$E,'Pasted Areas'!$K:$K,$B18,'Pasted Areas'!$C:$C,"*Front Door*",'Pasted Areas'!$H:$H,AH$7) -> 0 | AI18: =SUMIFS('Pasted Areas'!$E:$E,'Pasted Areas'!$K:$K,$B18,'Pasted Areas'!$C:$C,"*Front Door*",'Pasted Areas'!$H:$H,AI$7) -> 0 | AJ18: =SUMIFS('Pasted Areas'!$E:$E,'Pasted Areas'!$K:$K,$B18,'Pasted Areas'!$C:$C,"*Front Door*",'Pasted Areas'!$H:$H,AJ$7) -> 0 | AK18: =SUMIFS('Pasted Areas'!$E:$E,'Pasted Areas'!$K:$K,$B18,'Pasted Areas'!$C:$C,"*Front Door*",'Pasted Areas'!$H:$H,AK$7) -> 0 | AM18: =SUMIFS('Pasted Areas'!$E:$E,'Pasted Areas'!$K:$K,$B18,'Pasted Areas'!$C:$C,"*Glazing*",'Pasted Areas'!$H:$H,AM$7) -> 0 | AN18: =SUMIFS('Pasted Areas'!$E:$E,'Pasted Areas'!$K:$K,$B18,'Pasted Areas'!$C:$C,"*Glazing*",'Pasted Areas'!$H:$H,AN$7) -> 0 | AO18: =SUMIFS('Pasted Areas'!$E:$E,'Pasted Areas'!$K:$K,$B18,'Pasted Areas'!$C:$C,"*Glazing*",'Pasted Areas'!$H:$H,AO$7) -> 3.6 | AP18: =SUMIFS('Pasted Areas'!$E:$E,'Pasted Areas'!$K:$K,$B18,'Pasted Areas'!$C:$C,"*Glazing*",'Pasted Areas'!$H:$H,AP$7) -> 0 | AQ18: =SUMIFS('Pasted Areas'!$E:$E,'Pasted Areas'!$K:$K,$B18,'Pasted Areas'!$C:$C,"*Glazing*",'Pasted Areas'!$H:$H,AQ$7) -> 1.44 | AR18: =SUMIFS('Pasted Areas'!$E:$E,'Pasted Areas'!$K:$K,$B18,'Pasted Areas'!$C:$C,"*Glazing*",'Pasted Areas'!$H:$H,AR$7) -> 0 | AS18: =SUMIFS('Pasted Areas'!$E:$E,'Pasted Areas'!$K:$K,$B18,'Pasted Areas'!$C:$C,"*Glazing*",'Pasted Areas'!$H:$H,AS$7) -> 5.24 | AT18: =SUMIFS('Pasted Areas'!$E:$E,'Pasted Areas'!$K:$K,$B18,'Pasted Areas'!$C:$C,"*Glazing*",'Pasted Areas'!$H:$H,AT$7) -> 0 | AV18: =SUMIFS('Pasted Areas'!$E:$E,'Pasted Areas'!$K:$K,$B18,'Pasted Areas'!$C:$C,"*Roof Light*") -> 0 | AX18: 2 | AY18: 0 | AZ18: 1 | BA18: 0 | BB18: 1 | BC18: =AX18+AY18 -> 2 | BD18: =AZ18+BA18 -> 1 | BE18: =AZ18+BB18 -> 2 | BF18: =SUMIFS('Pasted Areas'!$E:$E,'Pasted Areas'!$K:$K,$B18,'Pasted Areas'!$C:$C,"*Cooling Area*") -> 0 | BS18: =SUM(AM18:AT18) -> 10.28 | BT18: =SUM(AH18:AK18) -> 0 | BU18: =SUM(M18:P18,V18:Z18,AC18:AE18,AH18:AV18) -> 79.92 | BV18: =I18*J18 -> 228.95 | BX18: =SUM(M18:S18,V18:AV18,BF18:BF18) -> 405.27
B19: Flat 12 | C19: 1 | D19: E | E19: Mid | F19: Mid | G19: 3 | I19: =SUM(AC19:AF19) -> 72.04 | J19: 2.5 | K19: =SUMIFS('Pasted Areas'!$E:$E,'Pasted Areas'!$K:$K,B19,'Pasted Areas'!$C:$C,"*Living*") -> 24.65 | M19: =SUMIFS('Pasted Areas'!$E:$E,'Pasted Areas'!$K:$K,$B19,'Pasted Areas'!$C:$C,"*External Wall Area 1*") -> 27.45 | N19: =SUMIFS('Pasted Areas'!$E:$E,'Pasted Areas'!$K:$K,$B19,'Pasted Areas'!$C:$C,"*External Wall Area 2*") -> 0 | O19: =SUMIFS('Pasted Areas'!$E:$E,'Pasted Areas'!$K:$K,$B19,'Pasted Areas'!$C:$C,"*External Wall Area 3*") -> 0 | P19: =SUMIFS('Pasted Areas'!$E:$E,'Pasted Areas'!$K:$K,$B19,'Pasted Areas'!$C:$C,"*External Wall Area 4*") -> 0 | Q19: =SUMIFS('Pasted Areas'!$E:$E,'Pasted Areas'!$K:$K,$B19,'Pasted Areas'!$C:$C,"*Party Walls to Corridors*") -> 32.77 | R19: =SUMIFS('Pasted Areas'!$E:$E,'Pasted Areas'!$K:$K,$B19,'Pasted Areas'!$C:$C,"*Party Walls to Dwelling*") -> 36.69 | S19: =SUMIFS('Pasted Areas'!$E:$E,'Pasted Areas'!$K:$K,$B19,'Pasted Areas'!$C:$C,"*Internal Partitions*") -> 67.14 | T19: =S19*2 -> 134.28 | V19: =SUMIFS('Pasted Areas'!$E:$E,'Pasted Areas'!$K:$K,$B19,'Pasted Areas'!$C:$C,"*SAP Roof 1*") -> 0 | W19: =SUMIFS('Pasted Areas'!$E:$E,'Pasted Areas'!$K:$K,$B19,'Pasted Areas'!$C:$C,"*SAP Roof 2*") -> 0 | X19: =SUMIFS('Pasted Areas'!$E:$E,'Pasted Areas'!$K:$K,$B19,'Pasted Areas'!$C:$C,"*SAP Roof 3*") -> 0 | Y19: =SUMIFS('Pasted Areas'!$E:$E,'Pasted Areas'!$K:$K,$B19,'Pasted Areas'!$C:$C,"*SAP Roof 4*") -> 0 | Z19: =SUMIFS('Pasted Areas'!$E:$E,'Pasted Areas'!$K:$K,$B19,'Pasted Areas'!$C:$C,"*SAP Roof 5*") -> 0 | AA19: =SUMIFS('Pasted Areas'!$E:$E,'Pasted Areas'!$K:$K,$B19,'Pasted Areas'!$C:$C,"*Party Ceiling*") -> 72.04 | AC19: =SUMIFS('Pasted Areas'!$E:$E,'Pasted Areas'!$K:$K,$B19,'Pasted Areas'!$C:$C,"*Ground Floor*") -> 0 | AD19: =SUMIFS('Pasted Areas'!$E:$E,'Pasted Areas'!$K:$K,$B19,'Pasted Areas'!$C:$C,"* Exposed Floor*") -> 0 | AE19: =SUMIFS('Pasted Areas'!$E:$E,'Pasted Areas'!$K:$K,$B19,'Pasted Areas'!$C:$C,"*Semi-Exposed Floor*") -> 0 | AF19: =SUMIFS('Pasted Areas'!$E:$E,'Pasted Areas'!$K:$K,$B19,'Pasted Areas'!$C:$C,"*Party Floor*") -> 72.04 | AH19: =SUMIFS('Pasted Areas'!$E:$E,'Pasted Areas'!$K:$K,$B19,'Pasted Areas'!$C:$C,"*Front Door*",'Pasted Areas'!$H:$H,AH$7) -> 0 | AI19: =SUMIFS('Pasted Areas'!$E:$E,'Pasted Areas'!$K:$K,$B19,'Pasted Areas'!$C:$C,"*Front Door*",'Pasted Areas'!$H:$H,AI$7) -> 0 | AJ19: =SUMIFS('Pasted Areas'!$E:$E,'Pasted Areas'!$K:$K,$B19,'Pasted Areas'!$C:$C,"*Front Door*",'Pasted Areas'!$H:$H,AJ$7) -> 0 | AK19: =SUMIFS('Pasted Areas'!$E:$E,'Pasted Areas'!$K:$K,$B19,'Pasted Areas'!$C:$C,"*Front Door*",'Pasted Areas'!$H:$H,AK$7) -> 0 | AM19: =SUMIFS('Pasted Areas'!$E:$E,'Pasted Areas'!$K:$K,$B19,'Pasted Areas'!$C:$C,"*Glazing*",'Pasted Areas'!$H:$H,AM$7) -> 0 | AN19: =SUMIFS('Pasted Areas'!$E:$E,'Pasted Areas'!$K:$K,$B19,'Pasted Areas'!$C:$C,"*Glazing*",'Pasted Areas'!$H:$H,AN$7) -> 0 | AO19: =SUMIFS('Pasted Areas'!$E:$E,'Pasted Areas'!$K:$K,$B19,'Pasted Areas'!$C:$C,"*Glazing*",'Pasted Areas'!$H:$H,AO$7) -> 0 | AP19: =SUMIFS('Pasted Areas'!$E:$E,'Pasted Areas'!$K:$K,$B19,'Pasted Areas'!$C:$C,"*Glazing*",'Pasted Areas'!$H:$H,AP$7) -> 0 | AQ19: =SUMIFS('Pasted Areas'!$E:$E,'Pasted Areas'!$K:$K,$B19,'Pasted Areas'!$C:$C,"*Glazing*",'Pasted Areas'!$H:$H,AQ$7) -> 0 | AR19: =SUMIFS('Pasted Areas'!$E:$E,'Pasted Areas'!$K:$K,$B19,'Pasted Areas'!$C:$C,"*Glazing*",'Pasted Areas'!$H:$H,AR$7) -> 0 | AS19: =SUMIFS('Pasted Areas'!$E:$E,'Pasted Areas'!$K:$K,$B19,'Pasted Areas'!$C:$C,"*Glazing*",'Pasted Areas'!$H:$H,AS$7) -> 8.84 | AT19: =SUMIFS('Pasted Areas'!$E:$E,'Pasted Areas'!$K:$K,$B19,'Pasted Areas'!$C:$C,"*Glazing*",'Pasted Areas'!$H:$H,AT$7) -> 0 | AV19: =SUMIFS('Pasted Areas'!$E:$E,'Pasted Areas'!$K:$K,$B19,'Pasted Areas'!$C:$C,"*Roof Light*") -> 0 | AX19: 2 | AY19: 0 | AZ19: 1 | BA19: 0 | BB19: 1 | BC19: =AX19+AY19 -> 2 | BD19: =AZ19+BA19 -> 1 | BE19: =AZ19+BB19 -> 2 | BF19: =SUMIFS('Pasted Areas'!$E:$E,'Pasted Areas'!$K:$K,$B19,'Pasted Areas'!$C:$C,"*Cooling Area*") -> 0 | BS19: =SUM(AM19:AT19) -> 8.84 | BT19: =SUM(AH19:AK19) -> 0 | BU19: =SUM(M19:P19,V19:Z19,AC19:AE19,AH19:AV19) -> 36.29 | BV19: =I19*J19 -> 180.1 | BX19: =SUM(M19:S19,V19:AV19,BF19:BF19) -> 316.97
B20: Flat 13 | C20: 2 | D20: SE | E20: End | F20: Top | G20: 2 | I20: =SUM(AC20:AF20) -> 71.69 | J20: 2.5 | K20: =SUMIFS('Pasted Areas'!$E:$E,'Pasted Areas'!$K:$K,B20,'Pasted Areas'!$C:$C,"*Living*") -> 25.64 | M20: =SUMIFS('Pasted Areas'!$E:$E,'Pasted Areas'!$K:$K,$B20,'Pasted Areas'!$C:$C,"*External Wall Area 1*") -> 41.96 | N20: =SUMIFS('Pasted Areas'!$E:$E,'Pasted Areas'!$K:$K,$B20,'Pasted Areas'!$C:$C,"*External Wall Area 2*") -> 0 | O20: =SUMIFS('Pasted Areas'!$E:$E,'Pasted Areas'!$K:$K,$B20,'Pasted Areas'!$C:$C,"*External Wall Area 3*") -> 0 | P20: =SUMIFS('Pasted Areas'!$E:$E,'Pasted Areas'!$K:$K,$B20,'Pasted Areas'!$C:$C,"*External Wall Area 4*") -> 0 | Q20: =SUMIFS('Pasted Areas'!$E:$E,'Pasted Areas'!$K:$K,$B20,'Pasted Areas'!$C:$C,"*Party Walls to Corridors*") -> 19.88 | R20: =SUMIFS('Pasted Areas'!$E:$E,'Pasted Areas'!$K:$K,$B20,'Pasted Areas'!$C:$C,"*Party Walls to Dwelling*") -> 26.98 | S20: =SUMIFS('Pasted Areas'!$E:$E,'Pasted Areas'!$K:$K,$B20,'Pasted Areas'!$C:$C,"*Internal Partitions*") -> 73.51 | T20: =S20*2 -> 147.02 | V20: =SUMIFS('Pasted Areas'!$E:$E,'Pasted Areas'!$K:$K,$B20,'Pasted Areas'!$C:$C,"*SAP Roof 1*") -> 0 | W20: =SUMIFS('Pasted Areas'!$E:$E,'Pasted Areas'!$K:$K,$B20,'Pasted Areas'!$C:$C,"*SAP Roof 2*") -> 0 | X20: =SUMIFS('Pasted Areas'!$E:$E,'Pasted Areas'!$K:$K,$B20,'Pasted Areas'!$C:$C,"*SAP Roof 3*") -> 0 | Y20: =SUMIFS('Pasted Areas'!$E:$E,'Pasted Areas'!$K:$K,$B20,'Pasted Areas'!$C:$C,"*SAP Roof 4*") -> 0 | Z20: =SUMIFS('Pasted Areas'!$E:$E,'Pasted Areas'!$K:$K,$B20,'Pasted Areas'!$C:$C,"*SAP Roof 5*") -> 71.69 | AA20: =SUMIFS('Pasted Areas'!$E:$E,'Pasted Areas'!$K:$K,$B20,'Pasted Areas'!$C:$C,"*Party Ceiling*") -> 0 | AC20: =SUMIFS('Pasted Areas'!$E:$E,'Pasted Areas'!$K:$K,$B20,'Pasted Areas'!$C:$C,"*Ground Floor*") -> 0 | AD20: =SUMIFS('Pasted Areas'!$E:$E,'Pasted Areas'!$K:$K,$B20,'Pasted Areas'!$C:$C,"* Exposed Floor*") -> 0 | AE20: =SUMIFS('Pasted Areas'!$E:$E,'Pasted Areas'!$K:$K,$B20,'Pasted Areas'!$C:$C,"*Semi-Exposed Floor*") -> 0 | AF20: =SUMIFS('Pasted Areas'!$E:$E,'Pasted Areas'!$K:$K,$B20,'Pasted Areas'!$C:$C,"*Party Floor*") -> 71.69 | AH20: =SUMIFS('Pasted Areas'!$E:$E,'Pasted Areas'!$K:$K,$B20,'Pasted Areas'!$C:$C,"*Front Door*",'Pasted Areas'!$H:$H,AH$7) -> 0 | AI20: =SUMIFS('Pasted Areas'!$E:$E,'Pasted Areas'!$K:$K,$B20,'Pasted Areas'!$C:$C,"*Front Door*",'Pasted Areas'!$H:$H,AI$7) -> 0 | AJ20: =SUMIFS('Pasted Areas'!$E:$E,'Pasted Areas'!$K:$K,$B20,'Pasted Areas'!$C:$C,"*Front Door*",'Pasted Areas'!$H:$H,AJ$7) -> 0 | AK20: =SUMIFS('Pasted Areas'!$E:$E,'Pasted Areas'!$K:$K,$B20,'Pasted Areas'!$C:$C,"*Front Door*",'Pasted Areas'!$H:$H,AK$7) -> 0 | AM20: =SUMIFS('Pasted Areas'!$E:$E,'Pasted Areas'!$K:$K,$B20,'Pasted Areas'!$C:$C,"*Glazing*",'Pasted Areas'!$H:$H,AM$7) -> 0 | AN20: =SUMIFS('Pasted Areas'!$E:$E,'Pasted Areas'!$K:$K,$B20,'Pasted Areas'!$C:$C,"*Glazing*",'Pasted Areas'!$H:$H,AN$7) -> 0 | AO20: =SUMIFS('Pasted Areas'!$E:$E,'Pasted Areas'!$K:$K,$B20,'Pasted Areas'!$C:$C,"*Glazing*",'Pasted Areas'!$H:$H,AO$7) -> 0 | AP20: =SUMIFS('Pasted Areas'!$E:$E,'Pasted Areas'!$K:$K,$B20,'Pasted Areas'!$C:$C,"*Glazing*",'Pasted Areas'!$H:$H,AP$7) -> 2.12 | AQ20: =SUMIFS('Pasted Areas'!$E:$E,'Pasted Areas'!$K:$K,$B20,'Pasted Areas'!$C:$C,"*Glazing*",'Pasted Areas'!$H:$H,AQ$7) -> 0 | AR20: =SUMIFS('Pasted Areas'!$E:$E,'Pasted Areas'!$K:$K,$B20,'Pasted Areas'!$C:$C,"*Glazing*",'Pasted Areas'!$H:$H,AR$7) -> 7.05 | AS20: =SUMIFS('Pasted Areas'!$E:$E,'Pasted Areas'!$K:$K,$B20,'Pasted Areas'!$C:$C,"*Glazing*",'Pasted Areas'!$H:$H,AS$7) -> 0 | AT20: =SUMIFS('Pasted Areas'!$E:$E,'Pasted Areas'!$K:$K,$B20,'Pasted Areas'!$C:$C,"*Glazing*",'Pasted Areas'!$H:$H,AT$7) -> 5.4 | AV20: =SUMIFS('Pasted Areas'!$E:$E,'Pasted Areas'!$K:$K,$B20,'Pasted Areas'!$C:$C,"*Roof Light*") -> 0 | AX20: 2 | AY20: 0 | AZ20: 1 | BA20: 0 | BB20: 1 | BC20: =AX20+AY20 -> 2 | BD20: =AZ20+BA20 -> 1 | BE20: =AZ20+BB20 -> 2 | BF20: =SUMIFS('Pasted Areas'!$E:$E,'Pasted Areas'!$K:$K,$B20,'Pasted Areas'!$C:$C,"*Cooling Area*") -> 0 | BS20: =SUM(AM20:AT20) -> 14.57 | BT20: =SUM(AH20:AK20) -> 0 | BU20: =SUM(M20:P20,V20:Z20,AC20:AE20,AH20:AV20) -> 128.22 | BV20: =I20*J20 -> 179.225 | BX20: =SUM(M20:S20,V20:AV20,BF20:BF20) -> 320.28
