Workbook
Name BridgeCodes: Data!$C$4:$C$47
Name JunctionCode: Data!$C$4:$C$47
Name JunctionXML: Data!$P$4:$P$47
Name Scheme: Data!$R$4:$R$8
Name SchemeXML: Data!$S$4:$S$8

Sheet Schedule
B2: THERMAL BRIDGE SCHEDULE
F3: Total in Sheet (m) | G3: =SUM(O7:AF30) -> 2037.15
F4: Total in Export (m) | G4: ='Pasted Bridges'!G2 -> 2037.15 | O4: Thermal Bridge Lengths (m) | AJ4: XML Export Helper Columns
B6: Ref | C6: Junction | E6: Default ψ (W/mK) | F6: ACDs ψ (W/mK) | G6: Notional ψ (W/mK) | I6: Sharing | J6: Shelter Factor | K6: Source | L6: Full ψ (W/mK) | M6: Adjusted ψ (W/mK) | O6: {=TRANSPOSE( _xlfn._xlws.SORT( _xlfn.UNIQUE( _xlfn._xlws.FILTER( 'Pasted Bridges'!F6:F1000, ('Pasted Bridges'!F6:F1000<>"") * ('Pasted Bridges'!F6:F1000<>0) ) ) ) )} -> Flat 01 | P6: Flat 02 | Q6: Flat 03 | R6: Flat 04 | S6: Flat 05 | T6: Flat 06 | U6: Flat 07 | V6: Flat 08 | W6: Flat 09 | X6: Flat 10 | Y6: Flat 11 | Z6: Flat 12 | AA6: Flat 13 | AB6: Flat 14 | AC6: Flat 15 | AD6: Flat 16 | AE6: Flat 17 | AF6: Flat 18 | AH6: Total (m) | AJ6: <Type Source> | AK6: <K1 Index> | AL6: <Refernce>
C7: {=_xlfn._xlws.SORT(_xlfn.UNIQUE(_xlfn._xlws.FILTER('Pasted Bridges'!B6:B1000,('Pasted Bridges'!B6:B1000<>"") *('Pasted Bridges'!B6:B1000<>0) )))} -> E02 Other lintels (including other steel lintels) [S1] [R1] | E7: {=INDEX(Data!L:L,MATCH(LEFT(C7,3),LEFT(Data!C:C,3),0))} -> 1 | F7: {=INDEX(Data!M:M,MATCH(LEFT(C7,3),LEFT(Data!C:C,3),0))} -> 0.3 | G7: {=INDEX(Data!N:N,MATCH(LEFT(C7,3),LEFT(Data!C:C,3),0))} -> 0.05 | I7: =IFERROR( VALUE( MID( C7, FIND("[S", C7) + 2, FIND("]", C7, FIND("[S", C7)) - FIND("[S", C7) - 2 ) ), "-" ) -> 1 | J7: =IFERROR( MID(C7, FIND("[R", C7) + 2, FIND("]", C7, FIND("[R", C7)) - FIND("[R", C7) - 2), "-" ) -> 1 | K7: Non Gov Scheme | L7: 0.017 | M7: =IF(I7="-","-",(L7/I7)*J7) -> 0.017 | O7: =SUMIFS('Pasted Bridges'!$G:$G,'Pasted Bridges'!$B:$B,$C7,'Pasted Bridges'!$F:$F,O$6) -> 6.2 | P7: =SUMIFS('Pasted Bridges'!$G:$G,'Pasted Bridges'!$B:$B,$C7,'Pasted Bridges'!$F:$F,P$6) -> 6.56 | Q7: =SUMIFS('Pasted Bridges'!$G:$G,'Pasted Bridges'!$B:$B,$C7,'Pasted Bridges'!$F:$F,Q$6) -> 4.98 | R7: =SUMIFS('Pasted Bridges'!$G:$G,'Pasted Bridges'!$B:$B,$C7,'Pasted Bridges'!$F:$F,R$6) -> 3.61 | S7: =SUMIFS('Pasted Bridges'!$G:$G,'Pasted Bridges'!$B:$B,$C7,'Pasted Bridges'!$F:$F,S$6) -> 5.65 | T7: =SUMIFS('Pasted Bridges'!$G:$G,'Pasted Bridges'!$B:$B,$C7,'Pasted Bridges'!$F:$F,T$6) -> 4.74 | U7: =SUMIFS('Pasted Bridges'!$G:$G,'Pasted Bridges'!$B:$B,$C7,'Pasted Bridges'!$F:$F,U$6) -> 8.01 | V7: =SUMIFS('Pasted Bridges'!$G:$G,'Pasted Bridges'!$B:$B,$C7,'Pasted Bridges'!$F:$F,V$6) -> 6.56 | ... AF7: =SUMIFS('Pasted Bridges'!$G:$G,'Pasted Bridges'!$B:$B,$C7,'Pasted Bridges'!$F:$F,AF$6) -> 4.74 | AH7: =SUM(O7:AF7) -> 98.84 | AJ7: =INDEX(SchemeXML,MATCH(K7,Scheme,0)) -> NonGovApprovedScheme | AK7: =INDEX(JunctionXML,MATCH(LEFT(C7,3),JunctionCode,0)) -> OtherLintels | AL7: ="Shared "&I7&", Shelter "&J7 -> Shared 1, Shelter 1
C8: E03 Sill [S1] [R1] | E8: {=INDEX(Data!L:L,MATCH(LEFT(C8,3),LEFT(Data!C:C,3),0))} -> 0.1 | F8: {=INDEX(Data!M:M,MATCH(LEFT(C8,3),LEFT(Data!C:C,3),0))} -> 0.04 | G8: {=INDEX(Data!N:N,MATCH(LEFT(C8,3),LEFT(Data!C:C,3),0))} -> 0.05 | I8: =IFERROR( VALUE( MID( C8, FIND("[S", C8) + 2, FIND("]", C8, FIND("[S", C8)) - FIND("[S", C8) - 2 ) ), "-" ) -> 1 | J8: =IFERROR( MID(C8, FIND("[R", C8) + 2, FIND("]", C8, FIND("[R", C8)) - FIND("[R", C8) - 2), "-" ) -> 1 | K8: Non Gov Scheme | L8: 0.022 | M8: =IF(I8="-","-",(L8/I8)*J8) -> 0.022 | O8: =SUMIFS('Pasted Bridges'!$G:$G,'Pasted Bridges'!$B:$B,$C8,'Pasted Bridges'!$F:$F,O$6) -> 2.26 | P8: =SUMIFS('Pasted Bridges'!$G:$G,'Pasted Bridges'!$B:$B,$C8,'Pasted Bridges'!$F:$F,P$6) -> 4.08 | Q8: =SUMIFS('Pasted Bridges'!$G:$G,'Pasted Bridges'!$B:$B,$C8,'Pasted Bridges'!$F:$F,Q$6) -> 4.08 | R8: =SUMIFS('Pasted Bridges'!$G:$G,'Pasted Bridges'!$B:$B,$C8,'Pasted Bridges'!$F:$F,R$6) -> 1.13 | S8: =SUMIFS('Pasted Bridges'!$G:$G,'Pasted Bridges'!$B:$B,$C8,'Pasted Bridges'!$F:$F,S$6) -> 3.17 | T8: =SUMIFS('Pasted Bridges'!$G:$G,'Pasted Bridges'!$B:$B,$C8,'Pasted Bridges'!$F:$F,T$6) -> 2.26 | U8: =SUMIFS('Pasted Bridges'!$G:$G,'Pasted Bridges'!$B:$B,$C8,'Pasted Bridges'!$F:$F,U$6) -> 4.52 | V8: =SUMIFS('Pasted Bridges'!$G:$G,'Pasted Bridges'!$B:$B,$C8,'Pasted Bridges'!$F:$F,V$6) -> 4.08 | ... AF8: =SUMIFS('Pasted Bridges'!$G:$G,'Pasted Bridges'!$B:$B,$C8,'Pasted Bridges'!$F:$F,AF$6) -> 2.26 | AH8: =SUM(O8:AF8) -> 55.46 | AJ8: =INDEX(SchemeXML,MATCH(K8,Scheme,0)) -> NonGovApprovedScheme | AK8: =INDEX(JunctionXML,MATCH(LEFT(C8,3),JunctionCode,0)) -> Sill | AL8: ="Shared "&I8&", Shelter "&J8 -> Shared 1, Shelter 1
C9: E04 Jamb [S1] [R1] | E9: {=INDEX(Data!L:L,MATCH(LEFT(C9,3),LEFT(Data!C:C,3),0))} -> 0.1 | F9: {=INDEX(Data!M:M,MATCH(LEFT(C9,3),LEFT(Data!C:C,3),0))} -> 0.05 | G9: {=INDEX(Data!N:N,MATCH(LEFT(C9,3),LEFT(Data!C:C,3),0))} -> 0.05 | I9: =IFERROR( VALUE( MID( C9, FIND("[S", C9) + 2, FIND("]", C9, FIND("[S", C9)) - FIND("[S", C9) - 2 ) ), "-" ) -> 1 | J9: =IFERROR( MID(C9, FIND("[R", C9) + 2, FIND("]", C9, FIND("[R", C9)) - FIND("[R", C9) - 2), "-" ) -> 1 | K9: Non Gov Scheme | L9: 0.017 | M9: =IF(I9="-","-",(L9/I9)*J9) -> 0.017 | O9: =SUMIFS('Pasted Bridges'!$G:$G,'Pasted Bridges'!$B:$B,$C9,'Pasted Bridges'!$F:$F,O$6) -> 14.7 | P9: =SUMIFS('Pasted Bridges'!$G:$G,'Pasted Bridges'!$B:$B,$C9,'Pasted Bridges'!$F:$F,P$6) -> 16.88 | Q9: =SUMIFS('Pasted Bridges'!$G:$G,'Pasted Bridges'!$B:$B,$C9,'Pasted Bridges'!$F:$F,Q$6) -> 16.84 | R9: =SUMIFS('Pasted Bridges'!$G:$G,'Pasted Bridges'!$B:$B,$C9,'Pasted Bridges'!$F:$F,R$6) -> 7.38 | S9: =SUMIFS('Pasted Bridges'!$G:$G,'Pasted Bridges'!$B:$B,$C9,'Pasted Bridges'!$F:$F,S$6) -> 13.66 | T9: =SUMIFS('Pasted Bridges'!$G:$G,'Pasted Bridges'!$B:$B,$C9,'Pasted Bridges'!$F:$F,T$6) -> 10.5 | U9: =SUMIFS('Pasted Bridges'!$G:$G,'Pasted Bridges'!$B:$B,$C9,'Pasted Bridges'!$F:$F,U$6) -> 21.02 | V9: =SUMIFS('Pasted Bridges'!$G:$G,'Pasted Bridges'!$B:$B,$C9,'Pasted Bridges'!$F:$F,V$6) -> 16.82 | ... AF9: =SUMIFS('Pasted Bridges'!$G:$G,'Pasted Bridges'!$B:$B,$C9,'Pasted Bridges'!$F:$F,AF$6) -> 10.5 | AH9: =SUM(O9:AF9) -> 252.4 | AJ9: =INDEX(SchemeXML,MATCH(K9,Scheme,0)) -> NonGovApprovedScheme | AK9: =INDEX(JunctionXML,MATCH(LEFT(C9,3),JunctionCode,0)) -> Jamb | AL9: ="Shared "&I9&", Shelter "&J9 -> Shared 1, Shelter 1
C10: E05 Ground floor (normal) [S1] [R1] | E10: {=INDEX(Data!L:L,MATCH(LEFT(C10,3),LEFT(Data!C:C,3),0))} -> 0.32 | F10: {=INDEX(Data!M:M,MATCH(LEFT(C10,3),LEFT(Data!C:C,3),0))} -> 0.16 | G10: {=INDEX(Data!N:N,MATCH(LEFT(C10,3),LEFT(Data!C:C,3),0))} -> 0.16 | I10: =IFERROR( VALUE( MID( C10, FIND("[S", C10) + 2, FIND("]", C10, FIND("[S", C10)) - FIND("[S", C10) - 2 ) ), "-" ) -> 1 | J10: =IFERROR( MID(C10, FIND("[R", C10) + 2, FIND("]", C10, FIND("[R", C10)) - FIND("[R", C10) - 2), "-" ) -> 1 | K10: Non Gov Scheme | L10: 0.074 | M10: =IF(I10="-","-",(L10/I10)*J10) -> 0.074 | O10: =SUMIFS('Pasted Bridges'!$G:$G,'Pasted Bridges'!$B:$B,$C10,'Pasted Bridges'!$F:$F,O$6) -> 15.47 | P10: =SUMIFS('Pasted Bridges'!$G:$G,'Pasted Bridges'!$B:$B,$C10,'Pasted Bridges'!$F:$F,P$6) -> 18.78 | Q10: =SUMIFS('Pasted Bridges'!$G:$G,'Pasted Bridges'!$B:$B,$C10,'Pasted Bridges'!$F:$F,Q$6) -> 12.4 | R10: =SUMIFS('Pasted Bridges'!$G:$G,'Pasted Bridges'!$B:$B,$C10,'Pasted Bridges'!$F:$F,R$6) -> 4.59 | S10: =SUMIFS('Pasted Bridges'!$G:$G,'Pasted Bridges'!$B:$B,$C10,'Pasted Bridges'!$F:$F,S$6) -> 28.8 | T10: =SUMIFS('Pasted Bridges'!$G:$G,'Pasted Bridges'!$B:$B,$C10,'Pasted Bridges'!$F:$F,T$6) -> 13.07 | U10: =SUMIFS('Pasted Bridges'!$G:$G,'Pasted Bridges'!$B:$B,$C10,'Pasted Bridges'!$F:$F,U$6) -> 0 | V10: =SUMIFS('Pasted Bridges'!$G:$G,'Pasted Bridges'!$B:$B,$C10,'Pasted Bridges'!$F:$F,V$6) -> 0 | ... AF10: =SUMIFS('Pasted Bridges'!$G:$G,'Pasted Bridges'!$B:$B,$C10,'Pasted Bridges'!$F:$F,AF$6) -> 0 | AH10: =SUM(O10:AF10) -> 93.11 | AJ10: =INDEX(SchemeXML,MATCH(K10,Scheme,0)) -> NonGovApprovedScheme | AK10: =INDEX(JunctionXML,MATCH(LEFT(C10,3),JunctionCode,0)) -> GroundFloorNormal | AL10: ="Shared "&I10&", Shelter "&J10 -> Shared 1, Shelter 1
C11: E07 Party floor between dwellings (in blocks of flats) [S2] [R1] | E11: {=INDEX(Data!L:L,MATCH(LEFT(C11,3),LEFT(Data!C:C,3),0))} -> 0.28 | F11: {=INDEX(Data!M:M,MATCH(LEFT(C11,3),LEFT(Data!C:C,3),0))} -> 0.14 | G11: {=INDEX(Data!N:N,MATCH(LEFT(C11,3),LEFT(Data!C:C,3),0))} -> 0.07 | I11: =IFERROR( VALUE( MID( C11, FIND("[S", C11) + 2, FIND("]", C11, FIND("[S", C11)) - FIND("[S", C11) - 2 ) ), "-" ) -> 2 | J11: =IFERROR( MID(C11, FIND("[R", C11) + 2, FIND("]", C11, FIND("[R", C11)) - FIND("[R", C11) - 2), "-" ) -> 1 | K11: Non Gov Scheme | L11: 0.074 | M11: =IF(I11="-","-",(L11/I11)*J11) -> 0.037 | O11: =SUMIFS('Pasted Bridges'!$G:$G,'Pasted Bridges'!$B:$B,$C11,'Pasted Bridges'!$F:$F,O$6) -> 10.29 | P11: =SUMIFS('Pasted Bridges'!$G:$G,'Pasted Bridges'!$B:$B,$C11,'Pasted Bridges'!$F:$F,P$6) -> 17.54 | Q11: =SUMIFS('Pasted Bridges'!$G:$G,'Pasted Bridges'!$B:$B,$C11,'Pasted Bridges'!$F:$F,Q$6) -> 12.4 | R11: =SUMIFS('Pasted Bridges'!$G:$G,'Pasted Bridges'!$B:$B,$C11,'Pasted Bridges'!$F:$F,R$6) -> 7.29 | S11: =SUMIFS('Pasted Bridges'!$G:$G,'Pasted Bridges'!$B:$B,$C11,'Pasted Bridges'!$F:$F,S$6) -> 28.8 | T11: =SUMIFS('Pasted Bridges'!$G:$G,'Pasted Bridges'!$B:$B,$C11,'Pasted Bridges'!$F:$F,T$6) -> 13.07 | U11: =SUMIFS('Pasted Bridges'!$G:$G,'Pasted Bridges'!$B:$B,$C11,'Pasted Bridges'!$F:$F,U$6) -> 30.06 | V11: =SUMIFS('Pasted Bridges'!$G:$G,'Pasted Bridges'!$B:$B,$C11,'Pasted Bridges'!$F:$F,V$6) -> 35.08 | ... AF11: =SUMIFS('Pasted Bridges'!$G:$G,'Pasted Bridges'!$B:$B,$C11,'Pasted Bridges'!$F:$F,AF$6) -> 13.07 | AH11: =SUM(O11:AF11) -> 376.5 | AJ11: =INDEX(SchemeXML,MATCH(K11,Scheme,0)) -> NonGovApprovedScheme | AK11: =INDEX(JunctionXML,MATCH(LEFT(C11,3),JunctionCode,0)) -> PartyFloor | AL11: ="Shared "&I11&", Shelter "&J11 -> Shared 2, Shelter 1
C12: E14 Flat roof [S1] [R1] | E12: {=INDEX(Data!L:L,MATCH(LEFT(C12,3),LEFT(Data!C:C,3),0))} -> 0.16 | F12: {=INDEX(Data!M:M,MATCH(LEFT(C12,3),LEFT(Data!C:C,3),0))} -> - | G12: {=INDEX(Data!N:N,MATCH(LEFT(C12,3),LEFT(Data!C:C,3),0))} -> 0.08 | I12: =IFERROR( VALUE( MID( C12, FIND("[S", C12) + 2, FIND("]", C12, FIND("[S", C12)) - FIND("[S", C12) - 2 ) ), "-" ) -> 1 | J12: =IFERROR( MID(C12, FIND("[R", C12) + 2, FIND("]", C12, FIND("[R", C12)) - FIND("[R", C12) - 2), "-" ) -> 1 | K12: Table K1 | L12: =E12 -> 0.16 | M12: =IF(I12="-","-",(L12/I12)*J12) -> 0.16 | O12: =SUMIFS('Pasted Bridges'!$G:$G,'Pasted Bridges'!$B:$B,$C12,'Pasted Bridges'!$F:$F,O$6) -> 5.18 | P12: =SUMIFS('Pasted Bridges'!$G:$G,'Pasted Bridges'!$B:$B,$C12,'Pasted Bridges'!$F:$F,P$6) -> 0 | Q12: =SUMIFS('Pasted Bridges'!$G:$G,'Pasted Bridges'!$B:$B,$C12,'Pasted Bridges'!$F:$F,Q$6) -> 0 | R12: =SUMIFS('Pasted Bridges'!$G:$G,'Pasted Bridges'!$B:$B,$C12,'Pasted Bridges'!$F:$F,R$6) -> 0 | S12: =SUMIFS('Pasted Bridges'!$G:$G,'Pasted Bridges'!$B:$B,$C12,'Pasted Bridges'!$F:$F,S$6) -> 0 | T12: =SUMIFS('Pasted Bridges'!$G:$G,'Pasted Bridges'!$B:$B,$C12,'Pasted Bridges'!$F:$F,T$6) -> 0 | U12: =SUMIFS('Pasted Bridges'!$G:$G,'Pasted Bridges'!$B:$B,$C12,'Pasted Bridges'!$F:$F,U$6) -> 0 | V12: =SUMIFS('Pasted Bridges'!$G:$G,'Pasted Bridges'!$B:$B,$C12,'Pasted Bridges'!$F:$F,V$6) -> 0 | ... AF12: =SUMIFS('Pasted Bridges'!$G:$G,'Pasted Bridges'!$B:$B,$C12,'Pasted Bridges'!$F:$F,AF$6) -> 7.4 | AH12: =SUM(O12:AF12) -> 37.16 | AJ12: =INDEX(SchemeXML,MATCH(K12,Scheme,0)) -> TableK1Default | AK12: =INDEX(JunctionXML,MATCH(LEFT(C12,3),JunctionCode,0)) -> FlatRoof | AL12: ="Shared "&I12&", Shelter "&J12 -> Shared 1, Shelter 1
C13: E15 Flat roof with parapet [S1] [R1] | E13: {=INDEX(Data!L:L,MATCH(LEFT(C13,3),LEFT(Data!C:C,3),0))} -> 0.3 | F13: {=INDEX(Data!M:M,MATCH(LEFT(C13,3),LEFT(Data!C:C,3),0))} -> - | G13: {=INDEX(Data!N:N,MATCH(LEFT(C13,3),LEFT(Data!C:C,3),0))} -> 0.56 | I13: =IFERROR( VALUE( MID( C13, FIND("[S", C13) + 2, FIND("]", C13, FIND("[S", C13)) - FIND("[S", C13) - 2 ) ), "-" ) -> 1 | J13: =IFERROR( MID(C13, FIND("[R", C13) + 2, FIND("]", C13, FIND("[R", C13)) - FIND("[R", C13) - 2), "-" ) -> 1 | K13: Table K1 | L13: =E13 -> 0.3 | M13: =IF(I13="-","-",(L13/I13)*J13) -> 0.3 | O13: =SUMIFS('Pasted Bridges'!$G:$G,'Pasted Bridges'!$B:$B,$C13,'Pasted Bridges'!$F:$F,O$6) -> 0 | P13: =SUMIFS('Pasted Bridges'!$G:$G,'Pasted Bridges'!$B:$B,$C13,'Pasted Bridges'!$F:$F,P$6) -> 0 | Q13: =SUMIFS('Pasted Bridges'!$G:$G,'Pasted Bridges'!$B:$B,$C13,'Pasted Bridges'!$F:$F,Q$6) -> 0 | R13: =SUMIFS('Pasted Bridges'!$G:$G,'Pasted Bridges'!$B:$B,$C13,'Pasted Bridges'!$F:$F,R$6) -> 0 | S13: =SUMIFS('Pasted Bridges'!$G:$G,'Pasted Bridges'!$B:$B,$C13,'Pasted Bridges'!$F:$F,S$6) -> 0 | T13: =SUMIFS('Pasted Bridges'!$G:$G,'Pasted Bridges'!$B:$B,$C13,'Pasted Bridges'!$F:$F,T$6) -> 0 | U13: =SUMIFS('Pasted Bridges'!$G:$G,'Pasted Bridges'!$B:$B,$C13,'Pasted Bridges'!$F:$F,U$6) -> 0 | V13: =SUMIFS('Pasted Bridges'!$G:$G,'Pasted Bridges'!$B:$B,$C13,'Pasted Bridges'!$F:$F,V$6) -> 0 | ... AF13: =SUMIFS('Pasted Bridges'!$G:$G,'Pasted Bridges'!$B:$B,$C13,'Pasted Bridges'!$F:$F,AF$6) -> 5.67 | AH13: =SUM(O13:AF13) -> 66.89 | AJ13: =INDEX(SchemeXML,MATCH(K13,Scheme,0)) -> TableK1Default | AK13: =INDEX(JunctionXML,MATCH(LEFT(C13,3),JunctionCode,0)) -> FlatRoofWithParapet | AL13: ="Shared "&I13&", Shelter "&J13 -> Shared 1, Shelter 1
C14: E16 Corner (normal) [S1] [R0.83] | E14: {=INDEX(Data!L:L,MATCH(LEFT(C14,3),LEFT(Data!C:C,3),0))} -> 0.18 | F14: {=INDEX(Data!M:M,MATCH(LEFT(C14,3),LEFT(Data!C:C,3),0))} -> 0.09 | G14: {=INDEX(Data!N:N,MATCH(LEFT(C14,3),LEFT(Data!C:C,3),0))} -> 0.09 | I14: =IFERROR( VALUE( MID( C14, FIND("[S", C14) + 2, FIND("]", C14, FIND("[S", C14)) - FIND("[S", C14) - 2 ) ), "-" ) -> 1 | J14: =IFERROR( MID(C14, FIND("[R", C14) + 2, FIND("]", C14, FIND("[R", C14)) - FIND("[R", C14) - 2), "-" ) -> 0.83 | K14: Non Gov Scheme | L14: 0.046 | M14: =IF(I14="-","-",(L14/I14)*J14) -> 0.03818 | O14: =SUMIFS('Pasted Bridges'!$G:$G,'Pasted Bridges'!$B:$B,$C14,'Pasted Bridges'!$F:$F,O$6) -> 2.77 | P14: =SUMIFS('Pasted Bridges'!$G:$G,'Pasted Bridges'!$B:$B,$C14,'Pasted Bridges'!$F:$F,P$6) -> 0 | Q14: =SUMIFS('Pasted Bridges'!$G:$G,'Pasted Bridges'!$B:$B,$C14,'Pasted Bridges'!$F:$F,Q$6) -> 0 | R14: =SUMIFS('Pasted Bridges'!$G:$G,'Pasted Bridges'!$B:$B,$C14,'Pasted Bridges'!$F:$F,R$6) -> 0 | S14: =SUMIFS('Pasted Bridges'!$G:$G,'Pasted Bridges'!$B:$B,$C14,'Pasted Bridges'!$F:$F,S$6) -> 0 | T14: =SUMIFS('Pasted Bridges'!$G:$G,'Pasted Bridges'!$B:$B,$C14,'Pasted Bridges'!$F:$F,T$6) -> 0 | U14: =SUMIFS('Pasted Bridges'!$G:$G,'Pasted Bridges'!$B:$B,$C14,'Pasted Bridges'!$F:$F,U$6) -> 0 | V14: =SUMIFS('Pasted Bridges'!$G:$G,'Pasted Bridges'!$B:$B,$C14,'Pasted Bridges'!$F:$F,V$6) -> 0 | ... AF14: =SUMIFS('Pasted Bridges'!$G:$G,'Pasted Bridges'!$B:$B,$C14,'Pasted Bridges'!$F:$F,AF$6) -> 0 | AH14: =SUM(O14:AF14) -> 2.77 | AJ14: =INDEX(SchemeXML,MATCH(K14,Scheme,0)) -> NonGovApprovedScheme | AK14: =INDEX(JunctionXML,MATCH(LEFT(C14,3),JunctionCode,0)) -> CornerNormal | AL14: ="Shared "&I14&", Shelter "&J14 -> Shared 1, Shelter 0.83
C15: E16 Corner (normal) [S1] [R1] | E15: {=INDEX(Data!L:L,MATCH(LEFT(C15,3),LEFT(Data!C:C,3),0))} -> 0.18 | F15: {=INDEX(Data!M:M,MATCH(LEFT(C15,3),LEFT(Data!C:C,3),0))} -> 0.09 | G15: {=INDEX(Data!N:N,MATCH(LEFT(C15,3),LEFT(Data!C:C,3),0))} -> 0.09 | I15: =IFERROR( VALUE( MID( C15, FIND("[S", C15) + 2, FIND("]", C15, FIND("[S", C15)) - FIND("[S", C15) - 2 ) ), "-" ) -> 1 | J15: =IFERROR( MID(C15, FIND("[R", C15) + 2, FIND("]", C15, FIND("[R", C15)) - FIND("[R", C15) - 2), "-" ) -> 1 | K15: Non Gov Scheme | L15: 0.046 | M15: =IF(I15="-","-",(L15/I15)*J15) -> 0.046 | O15: =SUMIFS('Pasted Bridges'!$G:$G,'Pasted Bridges'!$B:$B,$C15,'Pasted Bridges'!$F:$F,O$6) -> 5.54 | P15: =SUMIFS('Pasted Bridges'!$G:$G,'Pasted Bridges'!$B:$B,$C15,'Pasted Bridges'!$F:$F,P$6) -> 8.31 | Q15: =SUMIFS('Pasted Bridges'!$G:$G,'Pasted Bridges'!$B:$B,$C15,'Pasted Bridges'!$F:$F,Q$6) -> 5.54 | R15: =SUMIFS('Pasted Bridges'!$G:$G,'Pasted Bridges'!$B:$B,$C15,'Pasted Bridges'!$F:$F,R$6) -> 2.77 | S15: =SUMIFS('Pasted Bridges'!$G:$G,'Pasted Bridges'!$B:$B,$C15,'Pasted Bridges'!$F:$F,S$6) -> 8.31 | T15: =SUMIFS('Pasted Bridges'!$G:$G,'Pasted Bridges'!$B:$B,$C15,'Pasted Bridges'!$F:$F,T$6) -> 5.54 | U15: =SUMIFS('Pasted Bridges'!$G:$G,'Pasted Bridges'!$B:$B,$C15,'Pasted Bridges'!$F:$F,U$6) -> 5.54 | V15: =SUMIFS('Pasted Bridges'!$G:$G,'Pasted Bridges'!$B:$B,$C15,'Pasted Bridges'!$F:$F,V$6) -> 5.54 | ... AF15: =SUMIFS('Pasted Bridges'!$G:$G,'Pasted Bridges'!$B:$B,$C15,'Pasted Bridges'!$F:$F,AF$6) -> 5.72 | AH15: =SUM(O15:AF15) -> 103.57 | AJ15: =INDEX(SchemeXML,MATCH(K15,Scheme,0)) -> NonGovApprovedScheme | AK15: =INDEX(JunctionXML,MATCH(LEFT(C15,3),JunctionCode,0)) -> CornerNormal | AL15: ="Shared "&I15&", Shelter "&J15 -> Shared 1, Shelter 1
C16: E17 Corner (inverted – internal area greater than external area) [S1] [R0.83] | E16: {=INDEX(Data!L:L,MATCH(LEFT(C16,3),LEFT(Data!C:C,3),0))} -> 0 | F16: {=INDEX(Data!M:M,MATCH(LEFT(C16,3),LEFT(Data!C:C,3),0))} -> -0.09 | G16: {=INDEX(Data!N:N,MATCH(LEFT(C16,3),LEFT(Data!C:C,3),0))} -> -0.09 | I16: =IFERROR( VALUE( MID( C16, FIND("[S", C16) + 2, FIND("]", C16, FIND("[S", C16)) - FIND("[S", C16) - 2 ) ), "-" ) -> 1 | J16: =IFERROR( MID(C16, FIND("[R", C16) + 2, FIND("]", C16, FIND("[R", C16)) - FIND("[R", C16) - 2), "-" ) -> 0.83 | K16: Non Gov Scheme | L16: -0.088 | M16: =IF(I16="-","-",(L16/I16)*J16) -> -0.07304 | O16: =SUMIFS('Pasted Bridges'!$G:$G,'Pasted Bridges'!$B:$B,$C16,'Pasted Bridges'!$F:$F,O$6) -> 2.77 | P16: =SUMIFS('Pasted Bridges'!$G:$G,'Pasted Bridges'!$B:$B,$C16,'Pasted Bridges'!$F:$F,P$6) -> 0 | Q16: =SUMIFS('Pasted Bridges'!$G:$G,'Pasted Bridges'!$B:$B,$C16,'Pasted Bridges'!$F:$F,Q$6) -> 0 | R16: =SUMIFS('Pasted Bridges'!$G:$G,'Pasted Bridges'!$B:$B,$C16,'Pasted Bridges'!$F:$F,R$6) -> 0 | S16: =SUMIFS('Pasted Bridges'!$G:$G,'Pasted Bridges'!$B:$B,$C16,'Pasted Bridges'!$F:$F,S$6) -> 0 | T16: =SUMIFS('Pasted Bridges'!$G:$G,'Pasted Bridges'!$B:$B,$C16,'Pasted Bridges'!$F:$F,T$6) -> 0 | U16: =SUMIFS('Pasted Bridges'!$G:$G,'Pasted Bridges'!$B:$B,$C16,'Pasted Bridges'!$F:$F,U$6) -> 0 | V16: =SUMIFS('Pasted Bridges'!$G:$G,'Pasted Bridges'!$B:$B,$C16,'Pasted Bridges'!$F:$F,V$6) -> 0 | ... AF16: =SUMIFS('Pasted Bridges'!$G:$G,'Pasted Bridges'!$B:$B,$C16,'Pasted Bridges'!$F:$F,AF$6) -> 0 | AH16: =SUM(O16:AF16) -> 2.77 | AJ16: =INDEX(SchemeXML,MATCH(K16,Scheme,0)) -> NonGovApprovedScheme | AK16: =INDEX(JunctionXML,MATCH(LEFT(C16,3),JunctionCode,0)) -> CornerInverted | AL16: ="Shared "&I16&", Shelter "&J16 -> Shared 1, Shelter 0.83
C17: E17 Corner (inverted – internal area greater than external area) [S1] [R1] | E17: {=INDEX(Data!L:L,MATCH(LEFT(C17,3),LEFT(Data!C:C,3),0))} -> 0 | F17: {=INDEX(Data!M:M,MATCH(LEFT(C17,3),LEFT(Data!C:C,3),0))} -> -0.09 | G17: {=INDEX(Data!N:N,MATCH(LEFT(C17,3),LEFT(Data!C:C,3),0))} -> -0.09 | I17: =IFERROR( VALUE( MID( C17, FIND("[S", C17) + 2, FIND("]", C17, FIND("[S", C17)) - FIND("[S", C17) - 2 ) ), "-" ) -> 1 | J17: =IFERROR( MID(C17, FIND("[R", C17) + 2, FIND("]", C17, FIND("[R", C17)) - FIND("[R", C17) - 2), "-" ) -> 1 | K17: Non Gov Scheme | L17: -0.088 | M17: =IF(I17="-","-",(L17/I17)*J17) -> -0.088 | O17: =SUMIFS('Pasted Bridges'!$G:$G,'Pasted Bridges'!$B:$B,$C17,'Pasted Bridges'!$F:$F,O$6) -> 0 | P17: =SUMIFS('Pasted Bridges'!$G:$G,'Pasted Bridges'!$B:$B,$C17,'Pasted Bridges'!$F:$F,P$6) -> 2.77 | Q17: =SUMIFS('Pasted Bridges'!$G:$G,'Pasted Bridges'!$B:$B,$C17,'Pasted Bridges'!$F:$F,Q$6) -> 5.54 | R17: =SUMIFS('Pasted Bridges'!$G:$G,'Pasted Bridges'!$B:$B,$C17,'Pasted Bridges'!$F:$F,R$6) -> 2.77 | S17: =SUMIFS('Pasted Bridges'!$G:$G,'Pasted Bridges'!$B:$B,$C17,'Pasted Bridges'!$F:$F,S$6) -> 0 | T17: =SUMIFS('Pasted Bridges'!$G:$G,'Pasted Bridges'!$B:$B,$C17,'Pasted Bridges'!$F:$F,T$6) -> 2.77 | U17: =SUMIFS('Pasted Bridges'!$G:$G,'Pasted Bridges'!$B:$B,$C17,'Pasted Bridges'!$F:$F,U$6) -> 0 | V17: =SUMIFS('Pasted Bridges'!$G:$G,'Pasted Bridges'!$B:$B,$C17,'Pasted Bridges'!$F:$F,V$6) -> 2.77 | ... AF17: =SUMIFS('Pasted Bridges'!$G:$G,'Pasted Bridges'!$B:$B,$C17,'Pasted Bridges'!$F:$F,AF$6) -> 2.86 | AH17: =SUM(O17:AF17) -> 42 | AJ17: =INDEX(SchemeXML,MATCH(K17,Scheme,0)) -> NonGovApprovedScheme | AK17: =INDEX(JunctionXML,MATCH(LEFT(C17,3),JunctionCode,0)) -> CornerInverted | AL17: ="Shared "&I17&", Shelter "&J17 -> Shared 1, Shelter 1
C18: E18 Party wall between dwellings [S2] [R1] | E18: {=INDEX(Data!L:L,MATCH(LEFT(C18,3),LEFT(Data!C:C,3),0))} -> 0.24 | F18: {=INDEX(Data!M:M,MATCH(LEFT(C18,3),LEFT(Data!C:C,3),0))} -> 0.12 | G18: {=INDEX(Data!N:N,MATCH(LEFT(C18,3),LEFT(Data!C:C,3),0))} -> 0.06 | I18: =IFERROR( VALUE( MID( C18, FIND("[S", C18) + 2, FIND("]", C18, FIND("[S", C18)) - FIND("[S", C18) - 2 ) ), "-" ) -> 2 | J18: =IFERROR( MID(C18, FIND("[R", C18) + 2, FIND("]", C18, FIND("[R", C18)) - FIND("[R", C18) - 2), "-" ) -> 1 | K18: Non Gov Scheme | L18: =0.038*2 -> 0.076 | M18: =IF(I18="-","-",(L18/I18)*J18) -> 0.038 | O18: =SUMIFS('Pasted Bridges'!$G:$G,'Pasted Bridges'!$B:$B,$C18,'Pasted Bridges'!$F:$F,O$6) -> 0 | P18: =SUMIFS('Pasted Bridges'!$G:$G,'Pasted Bridges'!$B:$B,$C18,'Pasted Bridges'!$F:$F,P$6) -> 2.77 | Q18: =SUMIFS('Pasted Bridges'!$G:$G,'Pasted Bridges'!$B:$B,$C18,'Pasted Bridges'!$F:$F,Q$6) -> 5.54 | R18: =SUMIFS('Pasted Bridges'!$G:$G,'Pasted Bridges'!$B:$B,$C18,'Pasted Bridges'!$F:$F,R$6) -> 5.46 | S18: =SUMIFS('Pasted Bridges'!$G:$G,'Pasted Bridges'!$B:$B,$C18,'Pasted Bridges'!$F:$F,S$6) -> 0 | T18: =SUMIFS('Pasted Bridges'!$G:$G,'Pasted Bridges'!$B:$B,$C18,'Pasted Bridges'!$F:$F,T$6) -> 0 | U18: =SUMIFS('Pasted Bridges'!$G:$G,'Pasted Bridges'!$B:$B,$C18,'Pasted Bridges'!$F:$F,U$6) -> 2.77 | V18: =SUMIFS('Pasted Bridges'!$G:$G,'Pasted Bridges'!$B:$B,$C18,'Pasted Bridges'!$F:$F,V$6) -> 5.54 | ... AF18: =SUMIFS('Pasted Bridges'!$G:$G,'Pasted Bridges'!$B:$B,$C18,'Pasted Bridges'!$F:$F,AF$6) -> 0 | AH18: =SUM(O18:AF18) -> 47.55 | AJ18: =INDEX(SchemeXML,MATCH(K18,Scheme,0)) -> NonGovApprovedScheme | AK18: =INDEX(JunctionXML,MATCH(LEFT(C18,3),JunctionCode,0)) -> PartyWall | AL18: ="Shared "&I18&", Shelter "&J18 -> Shared 2, Shelter 1
C19: E20 Exposed floor (normal) [S1] [R0.83] | E19: {=INDEX(Data!L:L,MATCH(LEFT(C19,3),LEFT(Data!C:C,3),0))} -> 0.32 | F19: {=INDEX(Data!M:M,MATCH(LEFT(C19,3),LEFT(Data!C:C,3),0))} -> - | G19: {=INDEX(Data!N:N,MATCH(LEFT(C19,3),LEFT(Data!C:C,3),0))} -> 0.32 | I19: =IFERROR( VALUE( MID( C19, FIND("[S", C19) + 2, FIND("]", C19, FIND("[S", C19)) - FIND("[S", C19) - 2 ) ), "-" ) -> 1 | J19: =IFERROR( MID(C19, FIND("[R", C19) + 2, FIND("]", C19, FIND("[R", C19)) - FIND("[R", C19) - 2), "-" ) -> 0.83 | K19: Table K1 | L19: =E19 -> 0.32 | M19: =IF(I19="-","-",(L19/I19)*J19) -> 0.2656 | O19: =SUMIFS('Pasted Bridges'!$G:$G,'Pasted Bridges'!$B:$B,$C19,'Pasted Bridges'!$F:$F,O$6) -> 0 | P19: =SUMIFS('Pasted Bridges'!$G:$G,'Pasted Bridges'!$B:$B,$C19,'Pasted Bridges'!$F:$F,P$6) -> 0 | Q19: =SUMIFS('Pasted Bridges'!$G:$G,'Pasted Bridges'!$B:$B,$C19,'Pasted Bridges'!$F:$F,Q$6) -> 0 | R19: =SUMIFS('Pasted Bridges'!$G:$G,'Pasted Bridges'!$B:$B,$C19,'Pasted Bridges'!$F:$F,R$6) -> 0 | S19: =SUMIFS('Pasted Bridges'!$G:$G,'Pasted Bridges'!$B:$B,$C19,'Pasted Bridges'!$F:$F,S$6) -> 0 | T19: =SUMIFS('Pasted Bridges'!$G:$G,'Pasted Bridges'!$B:$B,$C19,'Pasted Bridges'!$F:$F,T$6) -> 0 | U19: =SUMIFS('Pasted Bridges'!$G:$G,'Pasted Bridges'!$B:$B,$C19,'Pasted Bridges'!$F:$F,U$6) -> 2.31 | V19: =SUMIFS('Pasted Bridges'!$G:$G,'Pasted Bridges'!$B:$B,$C19,'Pasted Bridges'!$F:$F,V$6) -> 0 | ... AF19: =SUMIFS('Pasted Bridges'!$G:$G,'Pasted Bridges'!$B:$B,$C19,'Pasted Bridges'!$F:$F,AF$6) -> 0 | AH19: =SUM(O19:AF19) -> 2.31 | AJ19: =INDEX(SchemeXML,MATCH(K19,Scheme,0)) -> TableK1Default | AK19: =INDEX(JunctionXML,MATCH(LEFT(C19,3),JunctionCode,0)) -> ExposedFloorNormal | AL19: ="Shared "&I19&", Shelter "&J19 -> Shared 1, Shelter 0.83
C20: E20 Exposed floor (normal) [S1] [R1] | E20: {=INDEX(Data!L:L,MATCH(LEFT(C20,3),LEFT(Data!C:C,3),0))} -> 0.32 | F20: {=INDEX(Data!M:M,MATCH(LEFT(C20,3),LEFT(Data!C:C,3),0))} -> - | G20: {=INDEX(Data!N:N,MATCH(LEFT(C20,3),LEFT(Data!C:C,3),0))} -> 0.32 | I20: =IFERROR( VALUE( MID( C20, FIND("[S", C20) + 2, FIND("]", C20, FIND("[S", C20)) - FIND("[S", C20) - 2 ) ), "-" ) -> 1 | J20: =IFERROR( MID(C20, FIND("[R", C20) + 2, FIND("]", C20, FIND("[R", C20)) - FIND("[R", C20) - 2), "-" ) -> 1 | K20: Table K1 | L20: =E20 -> 0.32 | M20: =IF(I20="-","-",(L20/I20)*J20) -> 0.32 | O20: =SUMIFS('Pasted Bridges'!$G:$G,'Pasted Bridges'!$B:$B,$C20,'Pasted Bridges'!$F:$F,O$6) -> 0 | P20: =SUMIFS('Pasted Bridges'!$G:$G,'Pasted Bridges'!$B:$B,$C20,'Pasted Bridges'!$F:$F,P$6) -> 0 | Q20: =SUMIFS('Pasted Bridges'!$G:$G,'Pasted Bridges'!$B:$B,$C20,'Pasted Bridges'!$F:$F,Q$6) -> 0 | R20: =SUMIFS('Pasted Bridges'!$G:$G,'Pasted Bridges'!$B:$B,$C20,'Pasted Bridges'!$F:$F,R$6) -> 0 | S20: =SUMIFS('Pasted Bridges'!$G:$G,'Pasted Bridges'!$B:$B,$C20,'Pasted Bridges'!$F:$F,S$6) -> 0 | T20: =SUMIFS('Pasted Bridges'!$G:$G,'Pasted Bridges'!$B:$B,$C20,'Pasted Bridges'!$F:$F,T$6) -> 0 | U20: =SUMIFS('Pasted Bridges'!$G:$G,'Pasted Bridges'!$B:$B,$C20,'Pasted Bridges'!$F:$F,U$6) -> 1.98 | V20: =SUMIFS('Pasted Bridges'!$G:$G,'Pasted Bridges'!$B:$B,$C20,'Pasted Bridges'!$F:$F,V$6) -> 0 | ... AF20: =SUMIFS('Pasted Bridges'!$G:$G,'Pasted Bridges'!$B:$B,$C20,'Pasted Bridges'!$F:$F,AF$6) -> 0 | AH20: =SUM(O20:AF20) -> 1.98 | AJ20: =INDEX(SchemeXML,MATCH(K20,Scheme,0)) -> TableK1Default | AK20: =INDEX(JunctionXML,MATCH(LEFT(C20,3),JunctionCode,0)) -> ExposedFloorNormal | AL20: ="Shared "&I20&", Shelter "&J20 -> Shared 1, Shelter 1
C21: E21 Exposed floor (inverted) [S2] [R1] | E21: {=INDEX(Data!L:L,MATCH(LEFT(C21,3),LEFT(Data!C:C,3),0))} -> 0.32 | F21: {=INDEX(Data!M:M,MATCH(LEFT(C21,3),LEFT(Data!C:C,3),0))} -> - | G21: {=INDEX(Data!N:N,MATCH(LEFT(C21,3),LEFT(Data!C:C,3),0))} -> 0.32 | I21: =IFERROR( VALUE( MID( C21, FIND("[S", C21) + 2, FIND("]", C21, FIND("[S", C21)) - FIND("[S", C21) - 2 ) ), "-" ) -> 2 | J21: =IFERROR( MID(C21, FIND("[R", C21) + 2, FIND("]", C21, FIND("[R", C21)) - FIND("[R", C21) - 2), "-" ) -> 1 | K21: Table K1 | L21: =E21 -> 0.32 | M21: =IF(I21="-","-",(L21/I21)*J21) -> 0.16 | O21: =SUMIFS('Pasted Bridges'!$G:$G,'Pasted Bridges'!$B:$B,$C21,'Pasted Bridges'!$F:$F,O$6) -> 0 | P21: =SUMIFS('Pasted Bridges'!$G:$G,'Pasted Bridges'!$B:$B,$C21,'Pasted Bridges'!$F:$F,P$6) -> 0 | Q21: =SUMIFS('Pasted Bridges'!$G:$G,'Pasted Bridges'!$B:$B,$C21,'Pasted Bridges'!$F:$F,Q$6) -> 0 | R21: =SUMIFS('Pasted Bridges'!$G:$G,'Pasted Bridges'!$B:$B,$C21,'Pasted Bridges'!$F:$F,R$6) -> 0 | S21: =SUMIFS('Pasted Bridges'!$G:$G,'Pasted Bridges'!$B:$B,$C21,'Pasted Bridges'!$F:$F,S$6) -> 0 | T21: =SUMIFS('Pasted Bridges'!$G:$G,'Pasted Bridges'!$B:$B,$C21,'Pasted Bridges'!$F:$F,T$6) -> 0 | U21: =SUMIFS('Pasted Bridges'!$G:$G,'Pasted Bridges'!$B:$B,$C21,'Pasted Bridges'!$F:$F,U$6) -> 2.05 | V21: =SUMIFS('Pasted Bridges'!$G:$G,'Pasted Bridges'!$B:$B,$C21,'Pasted Bridges'!$F:$F,V$6) -> 0 | ... AF21: =SUMIFS('Pasted Bridges'!$G:$G,'Pasted Bridges'!$B:$B,$C21,'Pasted Bridges'!$F:$F,AF$6) -> 0 | AH21: =SUM(O21:AF21) -> 2.05 | AJ21: =INDEX(SchemeXML,MATCH(K21,Scheme,0)) -> TableK1Default | AK21: =INDEX(JunctionXML,MATCH(LEFT(C21,3),JunctionCode,0)) -> ExposedFloorInverted | AL21: ="Shared "&I21&", Shelter "&J21 -> Shared 2, Shelter 1
C22: E24 Eaves (insulation at ceiling level - inverted) [S2] [R1] | E22: {=INDEX(Data!L:L,MATCH(LEFT(C22,3),LEFT(Data!C:C,3),0))} -> 0.15 | F22: {=INDEX(Data!M:M,MATCH(LEFT(C22,3),LEFT(Data!C:C,3),0))} -> - | G22: {=INDEX(Data!N:N,MATCH(LEFT(C22,3),LEFT(Data!C:C,3),0))} -> 0.24 | I22: =IFERROR( VALUE( MID( C22, FIND("[S", C22) + 2, FIND("]", C22, FIND("[S", C22)) - FIND("[S", C22) - 2 ) ), "-" ) -> 2 | J22: =IFERROR( MID(C22, FIND("[R", C22) + 2, FIND("]", C22, FIND("[R", C22)) - FIND("[R", C22) - 2), "-" ) -> 1 | K22: Table K1 | L22: =E22 -> 0.15 | M22: =IF(I22="-","-",(L22/I22)*J22) -> 0.075 | O22: =SUMIFS('Pasted Bridges'!$G:$G,'Pasted Bridges'!$B:$B,$C22,'Pasted Bridges'!$F:$F,O$6) -> 0 | P22: =SUMIFS('Pasted Bridges'!$G:$G,'Pasted Bridges'!$B:$B,$C22,'Pasted Bridges'!$F:$F,P$6) -> 0 | Q22: =SUMIFS('Pasted Bridges'!$G:$G,'Pasted Bridges'!$B:$B,$C22,'Pasted Bridges'!$F:$F,Q$6) -> 0 | R22: =SUMIFS('Pasted Bridges'!$G:$G,'Pasted Bridges'!$B:$B,$C22,'Pasted Bridges'!$F:$F,R$6) -> 0 | S22: =SUMIFS('Pasted Bridges'!$G:$G,'Pasted Bridges'!$B:$B,$C22,'Pasted Bridges'!$F:$F,S$6) -> 0 | T22: =SUMIFS('Pasted Bridges'!$G:$G,'Pasted Bridges'!$B:$B,$C22,'Pasted Bridges'!$F:$F,T$6) -> 0 | U22: =SUMIFS('Pasted Bridges'!$G:$G,'Pasted Bridges'!$B:$B,$C22,'Pasted Bridges'!$F:$F,U$6) -> 5.18 | V22: =SUMIFS('Pasted Bridges'!$G:$G,'Pasted Bridges'!$B:$B,$C22,'Pasted Bridges'!$F:$F,V$6) -> 0 | ... AF22: =SUMIFS('Pasted Bridges'!$G:$G,'Pasted Bridges'!$B:$B,$C22,'Pasted Bridges'!$F:$F,AF$6) -> 0 | AH22: =SUM(O22:AF22) -> 5.18 | AJ22: =INDEX(SchemeXML,MATCH(K22,Scheme,0)) -> TableK1Default | AK22: =INDEX(JunctionXML,MATCH(LEFT(C22,3),JunctionCode,0)) -> EavesAtCeilingInverted | AL22: ="Shared "&I22&", Shelter "&J22 -> Shared 2, Shelter 1
C23: E25 Staggered party wall between dwellings [S2] [R0.83] | E23: {=INDEX(Data!L:L,MATCH(LEFT(C23,3),LEFT(Data!C:C,3),0))} -> 0.24 | F23: {=INDEX(Data!M:M,MATCH(LEFT(C23,3),LEFT(Data!C:C,3),0))} -> - | G23: {=INDEX(Data!N:N,MATCH(LEFT(C23,3),LEFT(Data!C:C,3),0))} -> 0.06 | I23: =IFERROR( VALUE( MID( C23, FIND("[S", C23) + 2, FIND("]", C23, FIND("[S", C23)) - FIND("[S", C23) - 2 ) ), "-" ) -> 2 | J23: =IFERROR( MID(C23, FIND("[R", C23) + 2, FIND("]", C23, FIND("[R", C23)) - FIND("[R", C23) - 2), "-" ) -> 0.83 | K23: Table K1 | L23: =E23 -> 0.24 | M23: =IF(I23="-","-",(L23/I23)*J23) -> 0.0996 | O23: =SUMIFS('Pasted Bridges'!$G:$G,'Pasted Bridges'!$B:$B,$C23,'Pasted Bridges'!$F:$F,O$6) -> 2.77 | P23: =SUMIFS('Pasted Bridges'!$G:$G,'Pasted Bridges'!$B:$B,$C23,'Pasted Bridges'!$F:$F,P$6) -> 0 | Q23: =SUMIFS('Pasted Bridges'!$G:$G,'Pasted Bridges'!$B:$B,$C23,'Pasted Bridges'!$F:$F,Q$6) -> 0 | R23: =SUMIFS('Pasted Bridges'!$G:$G,'Pasted Bridges'!$B:$B,$C23,'Pasted Bridges'!$F:$F,R$6) -> 0 | S23: =SUMIFS('Pasted Bridges'!$G:$G,'Pasted Bridges'!$B:$B,$C23,'Pasted Bridges'!$F:$F,S$6) -> 0 | T23: =SUMIFS('Pasted Bridges'!$G:$G,'Pasted Bridges'!$B:$B,$C23,'Pasted Bridges'!$F:$F,T$6) -> 0 | U23: =SUMIFS('Pasted Bridges'!$G:$G,'Pasted Bridges'!$B:$B,$C23,'Pasted Bridges'!$F:$F,U$6) -> 0 | V23: =SUMIFS('Pasted Bridges'!$G:$G,'Pasted Bridges'!$B:$B,$C23,'Pasted Bridges'!$F:$F,V$6) -> 0 | ... AF23: =SUMIFS('Pasted Bridges'!$G:$G,'Pasted Bridges'!$B:$B,$C23,'Pasted Bridges'!$F:$F,AF$6) -> 0 | AH23: =SUM(O23:AF23) -> 2.77 | AJ23: =INDEX(SchemeXML,MATCH(K23,Scheme,0)) -> TableK1Default | AK23: =INDEX(JunctionXML,MATCH(LEFT(C23,3),JunctionCode,0)) -> StaggeredPart | AL23: ="Shared "&I23&", Shelter "&J23 -> Shared 2, Shelter 0.83
C24: E25 Staggered party wall between dwellings [S2] [R1] | E24: {=INDEX(Data!L:L,MATCH(LEFT(C24,3),LEFT(Data!C:C,3),0))} -> 0.24 | F24: {=INDEX(Data!M:M,MATCH(LEFT(C24,3),LEFT(Data!C:C,3),0))} -> - | G24: {=INDEX(Data!N:N,MATCH(LEFT(C24,3),LEFT(Data!C:C,3),0))} -> 0.06 | I24: =IFERROR( VALUE( MID( C24, FIND("[S", C24) + 2, FIND("]", C24, FIND("[S", C24)) - FIND("[S", C24) - 2 ) ), "-" ) -> 2 | J24: =IFERROR( MID(C24, FIND("[R", C24) + 2, FIND("]", C24, FIND("[R", C24)) - FIND("[R", C24) - 2), "-" ) -> 1 | K24: Table K1 | L24: =E24 -> 0.24 | M24: =IF(I24="-","-",(L24/I24)*J24) -> 0.12 | O24: =SUMIFS('Pasted Bridges'!$G:$G,'Pasted Bridges'!$B:$B,$C24,'Pasted Bridges'!$F:$F,O$6) -> 2.77 | P24: =SUMIFS('Pasted Bridges'!$G:$G,'Pasted Bridges'!$B:$B,$C24,'Pasted Bridges'!$F:$F,P$6) -> 2.77 | Q24: =SUMIFS('Pasted Bridges'!$G:$G,'Pasted Bridges'!$B:$B,$C24,'Pasted Bridges'!$F:$F,Q$6) -> 0 | R24: =SUMIFS('Pasted Bridges'!$G:$G,'Pasted Bridges'!$B:$B,$C24,'Pasted Bridges'!$F:$F,R$6) -> 2.77 | S24: =SUMIFS('Pasted Bridges'!$G:$G,'Pasted Bridges'!$B:$B,$C24,'Pasted Bridges'!$F:$F,S$6) -> 5.54 | T24: =SUMIFS('Pasted Bridges'!$G:$G,'Pasted Bridges'!$B:$B,$C24,'Pasted Bridges'!$F:$F,T$6) -> 5.54 | U24: =SUMIFS('Pasted Bridges'!$G:$G,'Pasted Bridges'!$B:$B,$C24,'Pasted Bridges'!$F:$F,U$6) -> 2.77 | V24: =SUMIFS('Pasted Bridges'!$G:$G,'Pasted Bridges'!$B:$B,$C24,'Pasted Bridges'!$F:$F,V$6) -> 0 | ... AF24: =SUMIFS('Pasted Bridges'!$G:$G,'Pasted Bridges'!$B:$B,$C24,'Pasted Bridges'!$F:$F,AF$6) -> 5.72 | AH24: =SUM(O24:AF24) -> 53.17 | AJ24: =INDEX(SchemeXML,MATCH(K24,Scheme,0)) -> TableK1Default | AK24: =INDEX(JunctionXML,MATCH(LEFT(C24,3),JunctionCode,0)) -> StaggeredPart | AL24: ="Shared "&I24&", Shelter "&J24 -> Shared 2, Shelter 1
C25: P01 Ground floor [S2] [R0.83] | E25: {=INDEX(Data!L:L,MATCH(LEFT(C25,3),LEFT(Data!C:C,3),0))} -> 0.32 | F25: {=INDEX(Data!M:M,MATCH(LEFT(C25,3),LEFT(Data!C:C,3),0))} -> - | G25: {=INDEX(Data!N:N,MATCH(LEFT(C25,3),LEFT(Data!C:C,3),0))} -> 0.08 | I25: =IFERROR( VALUE( MID( C25, FIND("[S", C25) + 2, FIND("]", C25, FIND("[S", C25)) - FIND("[S", C25) - 2 ) ), "-" ) -> 2 | J25: =IFERROR( MID(C25, FIND("[R", C25) + 2, FIND("]", C25, FIND("[R", C25)) - FIND("[R", C25) - 2), "-" ) -> 0.83 | K25: Non Gov Scheme | L25: =0.103*2 -> 0.206 | M25: =IF(I25="-","-",(L25/I25)*J25) -> 0.08549 | O25: =SUMIFS('Pasted Bridges'!$G:$G,'Pasted Bridges'!$B:$B,$C25,'Pasted Bridges'!$F:$F,O$6) -> 4.67 | P25: =SUMIFS('Pasted Bridges'!$G:$G,'Pasted Bridges'!$B:$B,$C25,'Pasted Bridges'!$F:$F,P$6) -> 0 | Q25: =SUMIFS('Pasted Bridges'!$G:$G,'Pasted Bridges'!$B:$B,$C25,'Pasted Bridges'!$F:$F,Q$6) -> 0 | R25: =SUMIFS('Pasted Bridges'!$G:$G,'Pasted Bridges'!$B:$B,$C25,'Pasted Bridges'!$F:$F,R$6) -> 0 | S25: =SUMIFS('Pasted Bridges'!$G:$G,'Pasted Bridges'!$B:$B,$C25,'Pasted Bridges'!$F:$F,S$6) -> 0 | T25: =SUMIFS('Pasted Bridges'!$G:$G,'Pasted Bridges'!$B:$B,$C25,'Pasted Bridges'!$F:$F,T$6) -> 0 | U25: =SUMIFS('Pasted Bridges'!$G:$G,'Pasted Bridges'!$B:$B,$C25,'Pasted Bridges'!$F:$F,U$6) -> 0 | V25: =SUMIFS('Pasted Bridges'!$G:$G,'Pasted Bridges'!$B:$B,$C25,'Pasted Bridges'!$F:$F,V$6) -> 0 | ... AF25: =SUMIFS('Pasted Bridges'!$G:$G,'Pasted Bridges'!$B:$B,$C25,'Pasted Bridges'!$F:$F,AF$6) -> 0 | AH25: =SUM(O25:AF25) -> 4.67 | AJ25: =INDEX(SchemeXML,MATCH(K25,Scheme,0)) -> NonGovApprovedScheme | AK25: =INDEX(JunctionXML,MATCH(LEFT(C25,3),JunctionCode,0)) -> GroundFloorWithPartyWall | AL25: ="Shared "&I25&", Shelter "&J25 -> Shared 2, Shelter 0.83
C26: P01 Ground floor [S2] [R1] | E26: {=INDEX(Data!L:L,MATCH(LEFT(C26,3),LEFT(Data!C:C,3),0))} -> 0.32 | F26: {=INDEX(Data!M:M,MATCH(LEFT(C26,3),LEFT(Data!C:C,3),0))} -> - | G26: {=INDEX(Data!N:N,MATCH(LEFT(C26,3),LEFT(Data!C:C,3),0))} -> 0.08 | I26: =IFERROR( VALUE( MID( C26, FIND("[S", C26) + 2, FIND("]", C26, FIND("[S", C26)) - FIND("[S", C26) - 2 ) ), "-" ) -> 2 | J26: =IFERROR( MID(C26, FIND("[R", C26) + 2, FIND("]", C26, FIND("[R", C26)) - FIND("[R", C26) - 2), "-" ) -> 1 | K26: Non Gov Scheme | L26: =0.103*2 -> 0.206 | M26: =IF(I26="-","-",(L26/I26)*J26) -> 0.103 | O26: =SUMIFS('Pasted Bridges'!$G:$G,'Pasted Bridges'!$B:$B,$C26,'Pasted Bridges'!$F:$F,O$6) -> 11.32 | P26: =SUMIFS('Pasted Bridges'!$G:$G,'Pasted Bridges'!$B:$B,$C26,'Pasted Bridges'!$F:$F,P$6) -> 16.3 | Q26: =SUMIFS('Pasted Bridges'!$G:$G,'Pasted Bridges'!$B:$B,$C26,'Pasted Bridges'!$F:$F,Q$6) -> 24.18 | R26: =SUMIFS('Pasted Bridges'!$G:$G,'Pasted Bridges'!$B:$B,$C26,'Pasted Bridges'!$F:$F,R$6) -> 24.13 | S26: =SUMIFS('Pasted Bridges'!$G:$G,'Pasted Bridges'!$B:$B,$C26,'Pasted Bridges'!$F:$F,S$6) -> 23.77 | T26: =SUMIFS('Pasted Bridges'!$G:$G,'Pasted Bridges'!$B:$B,$C26,'Pasted Bridges'!$F:$F,T$6) -> 25.03 | U26: =SUMIFS('Pasted Bridges'!$G:$G,'Pasted Bridges'!$B:$B,$C26,'Pasted Bridges'!$F:$F,U$6) -> 0 | V26: =SUMIFS('Pasted Bridges'!$G:$G,'Pasted Bridges'!$B:$B,$C26,'Pasted Bridges'!$F:$F,V$6) -> 0 | ... AF26: =SUMIFS('Pasted Bridges'!$G:$G,'Pasted Bridges'!$B:$B,$C26,'Pasted Bridges'!$F:$F,AF$6) -> 0 | AH26: =SUM(O26:AF26) -> 124.73 | AJ26: =INDEX(SchemeXML,MATCH(K26,Scheme,0)) -> NonGovApprovedScheme | AK26: =INDEX(JunctionXML,MATCH(LEFT(C26,3),JunctionCode,0)) -> GroundFloorWithPartyWall | AL26: ="Shared "&I26&", Shelter "&J26 -> Shared 2, Shelter 1
C27: P03 Intermediate floor between dwellings (in blocks of flats) | E27: {=INDEX(Data!L:L,MATCH(LEFT(C27,3),LEFT(Data!C:C,3),0))} -> 0 | F27: {=INDEX(Data!M:M,MATCH(LEFT(C27,3),LEFT(Data!C:C,3),0))} -> - | G27: {=INDEX(Data!N:N,MATCH(LEFT(C27,3),LEFT(Data!C:C,3),0))} -> 0 | I27: =IFERROR( VALUE( MID( C27, FIND("[S", C27) + 2, FIND("]", C27, FIND("[S", C27)) - FIND("[S", C27) - 2 ) ), "-" ) -> - | J27: =IFERROR( MID(C27, FIND("[R", C27) + 2, FIND("]", C27, FIND("[R", C27)) - FIND("[R", C27) - 2), "-" ) -> - | K27: Table K1 | L27: =E27 -> 0 | M27: 0 | O27: =SUMIFS('Pasted Bridges'!$G:$G,'Pasted Bridges'!$B:$B,$C27,'Pasted Bridges'!$F:$F,O$6) -> 11.32 | P27: =SUMIFS('Pasted Bridges'!$G:$G,'Pasted Bridges'!$B:$B,$C27,'Pasted Bridges'!$F:$F,P$6) -> 16.3 | Q27: =SUMIFS('Pasted Bridges'!$G:$G,'Pasted Bridges'!$B:$B,$C27,'Pasted Bridges'!$F:$F,Q$6) -> 24.18 | R27: =SUMIFS('Pasted Bridges'!$G:$G,'Pasted Bridges'!$B:$B,$C27,'Pasted Bridges'!$F:$F,R$6) -> 24.13 | S27: =SUMIFS('Pasted Bridges'!$G:$G,'Pasted Bridges'!$B:$B,$C27,'Pasted Bridges'!$F:$F,S$6) -> 23.77 | T27: =SUMIFS('Pasted Bridges'!$G:$G,'Pasted Bridges'!$B:$B,$C27,'Pasted Bridges'!$F:$F,T$6) -> 25.03 | U27: =SUMIFS('Pasted Bridges'!$G:$G,'Pasted Bridges'!$B:$B,$C27,'Pasted Bridges'!$F:$F,U$6) -> 31.54 | V27: =SUMIFS('Pasted Bridges'!$G:$G,'Pasted Bridges'!$B:$B,$C27,'Pasted Bridges'!$F:$F,V$6) -> 33.84 | ... AF27: =SUMIFS('Pasted Bridges'!$G:$G,'Pasted Bridges'!$B:$B,$C27,'Pasted Bridges'!$F:$F,AF$6) -> 25.03 | AH27: =SUM(O27:AF27) -> 530.43 | AJ27: =INDEX(SchemeXML,MATCH(K27,Scheme,0)) -> TableK1Default | AK27: =INDEX(JunctionXML,MATCH(LEFT(C27,3),JunctionCode,0)) -> PartyFloorWithPartyWall | AL27: ="Shared "&I27&", Shelter "&J27 -> Shared -, Shelter -
C28: P04 Roof (insulation at ceiling level) [S2] [R1] | E28: {=INDEX(Data!L:L,MATCH(LEFT(C28,3),LEFT(Data!C:C,3),0))} -> 0.48 | F28: {=INDEX(Data!M:M,MATCH(LEFT(C28,3),LEFT(Data!C:C,3),0))} -> - | G28: {=INDEX(Data!N:N,MATCH(LEFT(C28,3),LEFT(Data!C:C,3),0))} -> 0.12 | I28: =IFERROR( VALUE( MID( C28, FIND("[S", C28) + 2, FIND("]", C28, FIND("[S", C28)) - FIND("[S", C28) - 2 ) ), "-" ) -> 2 | J28: =IFERROR( MID(C28, FIND("[R", C28) + 2, FIND("]", C28, FIND("[R", C28)) - FIND("[R", C28) - 2), "-" ) -> 1 | K28: Independent | L28: 0.0523 | M28: =IF(I28="-","-",(L28/I28)*J28) -> 0.02615 | O28: =SUMIFS('Pasted Bridges'!$G:$G,'Pasted Bridges'!$B:$B,$C28,'Pasted Bridges'!$F:$F,O$6) -> 0 | P28: =SUMIFS('Pasted Bridges'!$G:$G,'Pasted Bridges'!$B:$B,$C28,'Pasted Bridges'!$F:$F,P$6) -> 0 | Q28: =SUMIFS('Pasted Bridges'!$G:$G,'Pasted Bridges'!$B:$B,$C28,'Pasted Bridges'!$F:$F,Q$6) -> 0 | R28: =SUMIFS('Pasted Bridges'!$G:$G,'Pasted Bridges'!$B:$B,$C28,'Pasted Bridges'!$F:$F,R$6) -> 0 | S28: =SUMIFS('Pasted Bridges'!$G:$G,'Pasted Bridges'!$B:$B,$C28,'Pasted Bridges'!$F:$F,S$6) -> 0 | T28: =SUMIFS('Pasted Bridges'!$G:$G,'Pasted Bridges'!$B:$B,$C28,'Pasted Bridges'!$F:$F,T$6) -> 0 | U28: =SUMIFS('Pasted Bridges'!$G:$G,'Pasted Bridges'!$B:$B,$C28,'Pasted Bridges'!$F:$F,U$6) -> 0 | V28: =SUMIFS('Pasted Bridges'!$G:$G,'Pasted Bridges'!$B:$B,$C28,'Pasted Bridges'!$F:$F,V$6) -> 0 | ... AF28: =SUMIFS('Pasted Bridges'!$G:$G,'Pasted Bridges'!$B:$B,$C28,'Pasted Bridges'!$F:$F,AF$6) -> 25.03 | AH28: =SUM(O28:AF28) -> 116 | AJ28: =INDEX(SchemeXML,MATCH(K28,Scheme,0)) -> IndependentlyAssessed | AK28: =INDEX(JunctionXML,MATCH(LEFT(C28,3),JunctionCode,0)) -> RoofAtCeilingWithPartyWall | AL28: ="Shared "&I28&", Shelter "&J28 -> Shared 2, Shelter 1
C29: P08 Exposed floor (inverted) [S2] [R0.83] | E29: {=INDEX(Data!L:L,MATCH(LEFT(C29,3),LEFT(Data!C:C,3),0))} -> 0.48 | F29: {=INDEX(Data!M:M,MATCH(LEFT(C29,3),LEFT(Data!C:C,3),0))} -> - | G29: {=INDEX(Data!N:N,MATCH(LEFT(C29,3),LEFT(Data!C:C,3),0))} -> 0.24 | I29: =IFERROR( VALUE( MID( C29, FIND("[S", C29) + 2, FIND("]", C29, FIND("[S", C29)) - FIND("[S", C29) - 2 ) ), "-" ) -> 2 | J29: =IFERROR( MID(C29, FIND("[R", C29) + 2, FIND("]", C29, FIND("[R", C29)) - FIND("[R", C29) - 2), "-" ) -> 0.83 | K29: Table K1 | L29: =E29 -> 0.48 | M29: =IF(I29="-","-",(L29/I29)*J29) -> 0.1992 | O29: =SUMIFS('Pasted Bridges'!$G:$G,'Pasted Bridges'!$B:$B,$C29,'Pasted Bridges'!$F:$F,O$6) -> 4.67 | P29: =SUMIFS('Pasted Bridges'!$G:$G,'Pasted Bridges'!$B:$B,$C29,'Pasted Bridges'!$F:$F,P$6) -> 0 | Q29: =SUMIFS('Pasted Bridges'!$G:$G,'Pasted Bridges'!$B:$B,$C29,'Pasted Bridges'!$F:$F,Q$6) -> 0 | R29: =SUMIFS('Pasted Bridges'!$G:$G,'Pasted Bridges'!$B:$B,$C29,'Pasted Bridges'!$F:$F,R$6) -> 0 | S29: =SUMIFS('Pasted Bridges'!$G:$G,'Pasted Bridges'!$B:$B,$C29,'Pasted Bridges'!$F:$F,S$6) -> 0 | T29: =SUMIFS('Pasted Bridges'!$G:$G,'Pasted Bridges'!$B:$B,$C29,'Pasted Bridges'!$F:$F,T$6) -> 0 | U29: =SUMIFS('Pasted Bridges'!$G:$G,'Pasted Bridges'!$B:$B,$C29,'Pasted Bridges'!$F:$F,U$6) -> 6.45 | V29: =SUMIFS('Pasted Bridges'!$G:$G,'Pasted Bridges'!$B:$B,$C29,'Pasted Bridges'!$F:$F,V$6) -> 0 | ... AF29: =SUMIFS('Pasted Bridges'!$G:$G,'Pasted Bridges'!$B:$B,$C29,'Pasted Bridges'!$F:$F,AF$6) -> 0 | AH29: =SUM(O29:AF29) -> 11.12 | AJ29: =INDEX(SchemeXML,MATCH(K29,Scheme,0)) -> TableK1Default | AK29: =INDEX(JunctionXML,MATCH(LEFT(C29,3),JunctionCode,0)) -> ExposedFloorInvertedWithPartyWall | AL29: ="Shared "&I29&", Shelter "&J29 -> Shared 2, Shelter 0.83
C30: P08 Exposed floor (inverted) [S3] [R1] | E30: {=INDEX(Data!L:L,MATCH(LEFT(C30,3),LEFT(Data!C:C,3),0))} -> 0.48 | F30: {=INDEX(Data!M:M,MATCH(LEFT(C30,3),LEFT(Data!C:C,3),0))} -> - | G30: {=INDEX(Data!N:N,MATCH(LEFT(C30,3),LEFT(Data!C:C,3),0))} -> 0.24 | I30: =IFERROR( VALUE( MID( C30, FIND("[S", C30) + 2, FIND("]", C30, FIND("[S", C30)) - FIND("[S", C30) - 2 ) ), "-" ) -> 3 | J30: =IFERROR( MID(C30, FIND("[R", C30) + 2, FIND("]", C30, FIND("[R", C30)) - FIND("[R", C30) - 2), "-" ) -> 1 | K30: Table K1 | L30: =E30 -> 0.48 | M30: =IF(I30="-","-",(L30/I30)*J30) -> 0.16 | O30: =SUMIFS('Pasted Bridges'!$G:$G,'Pasted Bridges'!$B:$B,$C30,'Pasted Bridges'!$F:$F,O$6) -> 0 | P30: =SUMIFS('Pasted Bridges'!$G:$G,'Pasted Bridges'!$B:$B,$C30,'Pasted Bridges'!$F:$F,P$6) -> 1.24 | Q30: =SUMIFS('Pasted Bridges'!$G:$G,'Pasted Bridges'!$B:$B,$C30,'Pasted Bridges'!$F:$F,Q$6) -> 0 | R30: =SUMIFS('Pasted Bridges'!$G:$G,'Pasted Bridges'!$B:$B,$C30,'Pasted Bridges'!$F:$F,R$6) -> 0 | S30: =SUMIFS('Pasted Bridges'!$G:$G,'Pasted Bridges'!$B:$B,$C30,'Pasted Bridges'!$F:$F,S$6) -> 0 | T30: =SUMIFS('Pasted Bridges'!$G:$G,'Pasted Bridges'!$B:$B,$C30,'Pasted Bridges'!$F:$F,T$6) -> 0 | U30: =SUMIFS('Pasted Bridges'!$G:$G,'Pasted Bridges'!$B:$B,$C30,'Pasted Bridges'!$F:$F,U$6) -> 1.24 | V30: =SUMIFS('Pasted Bridges'!$G:$G,'Pasted Bridges'!$B:$B,$C30,'Pasted Bridges'!$F:$F,V$6) -> 1.24 | ... AF30: =SUMIFS('Pasted Bridges'!$G:$G,'Pasted Bridges'!$B:$B,$C30,'Pasted Bridges'!$F:$F,AF$6) -> 0 | AH30: =SUM(O30:AF30) -> 3.72 | AJ30: =INDEX(SchemeXML,MATCH(K30,Scheme,0)) -> TableK1Default | AK30: =INDEX(JunctionXML,MATCH(LEFT(C30,3),JunctionCode,0)) -> ExposedFloorInvertedWithPartyWall | AL30: ="Shared "&I30&", Shelter "&J30 -> Shared 3, Shelter 1
O31: =SUM(O7:O30) -> 102.7 | P31: =SUM(P7:P30) -> 114.3 | Q31: =SUM(Q7:Q30) -> 115.68 | R31: =SUM(R7:R30) -> 86.03 | S31: =SUM(S7:S30) -> 141.47 | T31: =SUM(T7:T30) -> 107.55 | U31: =SUM(U7:U30) -> 125.44 | V31: =SUM(V7:V30) -> 111.47 | ... AF31: =SUM(AF7:AF30) -> 108
M32: Heat Loss (W/K)
M33: Default (W/K) | O33: =SUMPRODUCT($E$7:$E$30,O7:O30) -> 26.7402 | P33: =SUMPRODUCT($E$7:$E$30,P7:P30) -> 28.2134 | Q33: =SUMPRODUCT($E$7:$E$30,Q7:Q30) -> 24.5764 | R33: =SUMPRODUCT($E$7:$E$30,R7:R30) -> 18.1664 | S33: =SUMPRODUCT($E$7:$E$30,S7:S30) -> 35.0448 | T33: =SUMPRODUCT($E$7:$E$30,T7:T30) -> 24.1944 | U33: =SUMPRODUCT($E$7:$E$30,U7:U30) -> 27.8046 | V33: =SUMPRODUCT($E$7:$E$30,V7:V30) -> 21.3944 | ... AF33: =SUMPRODUCT($E$7:$E$30,AF7:AF30) -> 26.9774
M34: Notional (W/K) | O34: =SUMPRODUCT($G$7:$G$30,O7:O30) -> 7.9989 | P34: =SUMPRODUCT($G$7:$G$30,P7:P30) -> 8.0412 | Q34: =SUMPRODUCT($G$7:$G$30,Q7:Q30) -> 6.4138 | R34: =SUMPRODUCT($G$7:$G$30,R7:R30) -> 4.2749 | S34: =SUMPRODUCT($G$7:$G$30,S7:S30) -> 10.7299 | T34: =SUMPRODUCT($G$7:$G$30,T7:T30) -> 6.4652 | U34: =SUMPRODUCT($G$7:$G$30,U7:U30) -> 9.7303 | V34: =SUMPRODUCT($G$7:$G$30,V7:V30) -> 4.7079 | ... AF34: =SUMPRODUCT($G$7:$G$30,AF7:AF30) -> 9.1613
M35: Actual (W/K) | O35: =SUMPRODUCT($M$7:$M$30,O7:O30) -> 6.0213621 | P35: =SUMPRODUCT($M$7:$M$30,P7:P30) -> 4.9804 | Q35: =SUMPRODUCT($M$7:$M$30,Q7:Q30) -> 4.30548 | R35: =SUMPRODUCT($M$7:$M$30,R7:R30) -> 3.73001 | S35: =SUMPRODUCT($M$7:$M$30,S7:S30) -> 7.09018 | T35: =SUMPRODUCT($M$7:$M$30,T7:T30) -> 5.01354 | U35: =SUMPRODUCT($M$7:$M$30,U7:U30) -> 5.844546 | V35: =SUMPRODUCT($M$7:$M$30,V7:V30) -> 2.20518 | ... AF35: =SUMPRODUCT($M$7:$M$30,AF7:AF30) -> 5.0297645
